Workbook

Sheet Dashboard
A1: SmartRail — Project Dashboard
A2: Every figure is a formula. The only cell you ever edit here is the yellow start date in B3. | N2: Daily load — hours scheduled per day (amber over 9h)
A3: Project start (D1) | B3: 2026-09-29 | N3: D1 | O3: D2 | P3: D3 | Q3: D4 | R3: D5 | S3: D6 | T3: D7 | U3: D8 | V3: D9 | W3: D10 | X3: D11 | Y3: D12 | Z3: D13 | AA3: D14 | AB3: D15 | AC3: D16 | AD3: D17 | AE3: D18 | AF3: D19 | AG3: D20 | AH3: D21
A4: Today | B4: =TODAY() -> 46296 | N4: =SUMIFS(WBS!$J$5:'WBS'!$J$144,WBS!$F$5:'WBS'!$F$144,1,WBS!$B$5:'WBS'!$B$144,3) -> 10 | O4: =SUMIFS(WBS!$J$5:'WBS'!$J$144,WBS!$F$5:'WBS'!$F$144,2,WBS!$B$5:'WBS'!$B$144,3) -> 10 | P4: =SUMIFS(WBS!$J$5:'WBS'!$J$144,WBS!$F$5:'WBS'!$F$144,3,WBS!$B$5:'WBS'!$B$144,3) -> 8.5 | Q4: =SUMIFS(WBS!$J$5:'WBS'!$J$144,WBS!$F$5:'WBS'!$F$144,4,WBS!$B$5:'WBS'!$B$144,3) -> 8 | R4: =SUMIFS(WBS!$J$5:'WBS'!$J$144,WBS!$F$5:'WBS'!$F$144,5,WBS!$B$5:'WBS'!$B$144,3) -> 8 | S4: =SUMIFS(WBS!$J$5:'WBS'!$J$144,WBS!$F$5:'WBS'!$F$144,6,WBS!$B$5:'WBS'!$B$144,3) -> 9 | T4: =SUMIFS(WBS!$J$5:'WBS'!$J$144,WBS!$F$5:'WBS'!$F$144,7,WBS!$B$5:'WBS'!$B$144,3) -> 8 | U4: =SUMIFS(WBS!$J$5:'WBS'!$J$144,WBS!$F$5:'WBS'!$F$144,8,WBS!$B$5:'WBS'!$B$144,3) -> 8 | V4: =SUMIFS(WBS!$J$5:'WBS'!$J$144,WBS!$F$5:'WBS'!$F$144,9,WBS!$B$5:'WBS'!$B$144,3) -> 8 | W4: =SUMIFS(WBS!$J$5:'WBS'!$J$144,WBS!$F$5:'WBS'!$F$144,10,WBS!$B$5:'WBS'!$B$144,3) -> 8 | X4: =SUMIFS(WBS!$J$5:'WBS'!$J$144,WBS!$F$5:'WBS'!$F$144,11,WBS!$B$5:'WBS'!$B$144,3) -> 8 | Y4: =SUMIFS(WBS!$J$5:'WBS'!$J$144,WBS!$F$5:'WBS'!$F$144,12,WBS!$B$5:'WBS'!$B$144,3) -> 8 | Z4: =SUMIFS(WBS!$J$5:'WBS'!$J$144,WBS!$F$5:'WBS'!$F$144,13,WBS!$B$5:'WBS'!$B$144,3) -> 8 | AA4: =SUMIFS(WBS!$J$5:'WBS'!$J$144,WBS!$F$5:'WBS'!$F$144,14,WBS!$B$5:'WBS'!$B$144,3) -> 9.5 | AB4: =SUMIFS(WBS!$J$5:'WBS'!$J$144,WBS!$F$5:'WBS'!$F$144,15,WBS!$B$5:'WBS'!$B$144,3) -> 8 | AC4: =SUMIFS(WBS!$J$5:'WBS'!$J$144,WBS!$F$5:'WBS'!$F$144,16,WBS!$B$5:'WBS'!$B$144,3) -> 8 | AD4: =SUMIFS(WBS!$J$5:'WBS'!$J$144,WBS!$F$5:'WBS'!$F$144,17,WBS!$B$5:'WBS'!$B$144,3) -> 8 | AE4: =SUMIFS(WBS!$J$5:'WBS'!$J$144,WBS!$F$5:'WBS'!$F$144,18,WBS!$B$5:'WBS'!$B$144,3) -> 8 | AF4: =SUMIFS(WBS!$J$5:'WBS'!$J$144,WBS!$F$5:'WBS'!$F$144,19,WBS!$B$5:'WBS'!$B$144,3) -> 7.5 | AG4: =SUMIFS(WBS!$J$5:'WBS'!$J$144,WBS!$F$5:'WBS'!$F$144,20,WBS!$B$5:'WBS'!$B$144,3) -> 7 | AH4: =SUMIFS(WBS!$J$5:'WBS'!$J$144,WBS!$F$5:'WBS'!$F$144,21,WBS!$B$5:'WBS'!$B$144,3) -> 6.5
A5: Current day | B5: =MAX(0,$B$4-$B$3+1) -> 3
A6: Total days | B6: 21
A7: Days to submission | B7: =MAX(0,$B$6-$B$5) -> 18
A9: Progress | D9: Phase rollup
A10: Tasks in scope | B10: =COUNTIFS(WBS!$B$5:'WBS'!$B$144,3,WBS!$L$5:'WBS'!$L$144,"<>Deferred") -> 96 | D10: # | E10: Phase | F10: Days | G10: Est h | H10: Logged | I10: % Done
A11: Done | B11: =COUNTIFS(WBS!$B$5:'WBS'!$B$144,3,WBS!$L$5:'WBS'!$L$144,"Done") -> 2 | D11: 1 | E11: =INDEX(WBS!$D$5:$D$144,MATCH("1",WBS!$A$5:$A$144,0)) -> Discovery | F11: ="D"&INDEX(WBS!$F$5:$F$144,MATCH("1",WBS!$A$5:$A$144,0))&"-D"&INDEX(WBS!$T$5:$T$144,MATCH("1",WBS!$A$5:$A$144,0)) -> D1-D3 | G11: =INDEX(WBS!$J$5:$J$144,MATCH("1",WBS!$A$5:$A$144,0)) -> 28.5 | H11: =INDEX(WBS!$K$5:$K$144,MATCH("1",WBS!$A$5:$A$144,0)) -> 0 | I11: =INDEX(WBS!$M$5:$M$144,MATCH("1",WBS!$A$5:$A$144,0)) -> 0.10526316
A12: In progress | B12: =COUNTIFS(WBS!$B$5:'WBS'!$B$144,3,WBS!$L$5:'WBS'!$L$144,"Doing") -> 0 | D12: 2 | E12: =INDEX(WBS!$D$5:$D$144,MATCH("2",WBS!$A$5:$A$144,0)) -> Design and Decide | F12: ="D"&INDEX(WBS!$F$5:$F$144,MATCH("2",WBS!$A$5:$A$144,0))&"-D"&INDEX(WBS!$T$5:$T$144,MATCH("2",WBS!$A$5:$A$144,0)) -> D4-D5 | G12: =INDEX(WBS!$J$5:$J$144,MATCH("2",WBS!$A$5:$A$144,0)) -> 16 | H12: =INDEX(WBS!$K$5:$K$144,MATCH("2",WBS!$A$5:$A$144,0)) -> 0 | I12: =INDEX(WBS!$M$5:$M$144,MATCH("2",WBS!$A$5:$A$144,0)) -> 0
A13: Blocked | B13: =COUNTIFS(WBS!$B$5:'WBS'!$B$144,3,WBS!$L$5:'WBS'!$L$144,"Blocked") -> 0 | D13: 3 | E13: =INDEX(WBS!$D$5:$D$144,MATCH("3",WBS!$A$5:$A$144,0)) -> Backend Spine | F13: ="D"&INDEX(WBS!$F$5:$F$144,MATCH("3",WBS!$A$5:$A$144,0))&"-D"&INDEX(WBS!$T$5:$T$144,MATCH("3",WBS!$A$5:$A$144,0)) -> D6-D7 | G13: =INDEX(WBS!$J$5:$J$144,MATCH("3",WBS!$A$5:$A$144,0)) -> 17 | H13: =INDEX(WBS!$K$5:$K$144,MATCH("3",WBS!$A$5:$A$144,0)) -> 0 | I13: =INDEX(WBS!$M$5:$M$144,MATCH("3",WBS!$A$5:$A$144,0)) -> 0
A14: Not started | B14: =COUNTIFS(WBS!$B$5:'WBS'!$B$144,3,WBS!$L$5:'WBS'!$L$144,"To do") -> 94 | D14: 4 | E14: =INDEX(WBS!$D$5:$D$144,MATCH("4",WBS!$A$5:$A$144,0)) -> Live Core | F14: ="D"&INDEX(WBS!$F$5:$F$144,MATCH("4",WBS!$A$5:$A$144,0))&"-D"&INDEX(WBS!$T$5:$T$144,MATCH("4",WBS!$A$5:$A$144,0)) -> D8-D9 | G14: =INDEX(WBS!$J$5:$J$144,MATCH("4",WBS!$A$5:$A$144,0)) -> 16 | H14: =INDEX(WBS!$K$5:$K$144,MATCH("4",WBS!$A$5:$A$144,0)) -> 0 | I14: =INDEX(WBS!$M$5:$M$144,MATCH("4",WBS!$A$5:$A$144,0)) -> 0
A15: Deferred | B15: =COUNTIFS(WBS!$B$5:'WBS'!$B$144,3,WBS!$L$5:'WBS'!$L$144,"Deferred") -> 0 | D15: 5 | E15: =INDEX(WBS!$D$5:$D$144,MATCH("5",WBS!$A$5:$A$144,0)) -> Client Applications | F15: ="D"&INDEX(WBS!$F$5:$F$144,MATCH("5",WBS!$A$5:$A$144,0))&"-D"&INDEX(WBS!$T$5:$T$144,MATCH("5",WBS!$A$5:$A$144,0)) -> D10-D13 | G15: =INDEX(WBS!$J$5:$J$144,MATCH("5",WBS!$A$5:$A$144,0)) -> 32 | H15: =INDEX(WBS!$K$5:$K$144,MATCH("5",WBS!$A$5:$A$144,0)) -> 0 | I15: =INDEX(WBS!$M$5:$M$144,MATCH("5",WBS!$A$5:$A$144,0)) -> 0
A16: Overall % complete (hour weighted) | B16: =IFERROR(SUMPRODUCT((WBS!$B$5:'WBS'!$B$144=3)*(WBS!$L$5:'WBS'!$L$144<>"Deferred")*WBS!$J$5:'WBS'!$J$144*WBS!$M$5:'WBS'!$M$144)/SUMPRODUCT((WBS!$B$5:'WBS'!$B$144=3)*(WBS!$L$5:'WBS'!$L$144<>"Deferred")*WBS!$J$5:'WBS'!$J$144),0) -> 0.01744186 | D16: 6 | E16: =INDEX(WBS!$D$5:$D$144,MATCH("6",WBS!$A$5:$A$144,0)) -> External Integration | F16: ="D"&INDEX(WBS!$F$5:$F$144,MATCH("6",WBS!$A$5:$A$144,0))&"-D"&INDEX(WBS!$T$5:$T$144,MATCH("6",WBS!$A$5:$A$144,0)) -> D14-D14 | G16: =INDEX(WBS!$J$5:$J$144,MATCH("6",WBS!$A$5:$A$144,0)) -> 9.5 | H16: =INDEX(WBS!$K$5:$K$144,MATCH("6",WBS!$A$5:$A$144,0)) -> 0 | I16: =INDEX(WBS!$M$5:$M$144,MATCH("6",WBS!$A$5:$A$144,0)) -> 0
A17: Slipped tasks (past due, not done) | B17: =COUNTIFS(WBS!$B$5:'WBS'!$B$144,3,WBS!$F$5:'WBS'!$F$144,"<"&$B$5,WBS!$L$5:'WBS'!$L$144,"<>Done",WBS!$L$5:'WBS'!$L$144,"<>Deferred") -> 8 | D17: 7 | E17: =INDEX(WBS!$D$5:$D$144,MATCH("7",WBS!$A$5:$A$144,0)) -> Harden and Prove | F17: ="D"&INDEX(WBS!$F$5:$F$144,MATCH("7",WBS!$A$5:$A$144,0))&"-D"&INDEX(WBS!$T$5:$T$144,MATCH("7",WBS!$A$5:$A$144,0)) -> D15-D18 | G17: =INDEX(WBS!$J$5:$J$144,MATCH("7",WBS!$A$5:$A$144,0)) -> 32 | H17: =INDEX(WBS!$K$5:$K$144,MATCH("7",WBS!$A$5:$A$144,0)) -> 0 | I17: =INDEX(WBS!$M$5:$M$144,MATCH("7",WBS!$A$5:$A$144,0)) -> 0
A18: Estimated hours in scope | B18: =SUMPRODUCT((WBS!$B$5:'WBS'!$B$144=3)*(WBS!$L$5:'WBS'!$L$144<>"Deferred")*WBS!$J$5:'WBS'!$J$144) -> 172 | D18: 8 | E18: =INDEX(WBS!$D$5:$D$144,MATCH("8",WBS!$A$5:$A$144,0)) -> Evidence and Demo | F18: ="D"&INDEX(WBS!$F$5:$F$144,MATCH("8",WBS!$A$5:$A$144,0))&"-D"&INDEX(WBS!$T$5:$T$144,MATCH("8",WBS!$A$5:$A$144,0)) -> D19-D21 | G18: =INDEX(WBS!$J$5:$J$144,MATCH("8",WBS!$A$5:$A$144,0)) -> 21 | H18: =INDEX(WBS!$K$5:$K$144,MATCH("8",WBS!$A$5:$A$144,0)) -> 0 | I18: =INDEX(WBS!$M$5:$M$144,MATCH("8",WBS!$A$5:$A$144,0)) -> 0
A19: Hours logged | B19: =SUMPRODUCT((WBS!$B$5:'WBS'!$B$144=3)*WBS!$K$5:'WBS'!$K$144) -> 0
A20: Estimate accuracy on completed work | B20: =IFERROR(SUMPRODUCT((WBS!$B$5:'WBS'!$B$144=3)*(WBS!$L$5:'WBS'!$L$144="Done")*WBS!$K$5:'WBS'!$K$144)/SUMPRODUCT((WBS!$B$5:'WBS'!$B$144=3)*(WBS!$L$5:'WBS'!$L$144="Done")*WBS!$J$5:'WBS'!$J$144),0) -> 0
D21: Gates
D22: Gate | E22: Description | F22: Day | G22: Date | H22: Open | I22: Status
A23: AI usage | D23: G1 | E23: Requirements frozen | F23: 3 | G23: =$B$3+$F23-1 -> 46296 | H23: =COUNTIFS(WBS!$B$5:'WBS'!$B$144,3,WBS!$F$5:'WBS'!$F$144,"<="&$F23,WBS!$L$5:'WBS'!$L$144,"<>Done",WBS!$L$5:'WBS'!$L$144,"<>Deferred") -> 14 | I23: =IF($H23=0,"Cleared",IF($F23<$B$5,"MISSED","Open")) -> Open
A24: Logged AI contributions | B24: ='AI Summary'!$B$5 -> 2 | D24: G2 | E24: Spine runs and CI green | F24: 7 | G24: =$B$3+$F24-1 -> 46300 | H24: =COUNTIFS(WBS!$B$5:'WBS'!$B$144,3,WBS!$F$5:'WBS'!$F$144,"<="&$F24,WBS!$L$5:'WBS'!$L$144,"<>Done",WBS!$L$5:'WBS'!$L$144,"<>Deferred") -> 33 | I24: =IF($H24=0,"Cleared",IF($F24<$B$5,"MISSED","Open")) -> Open
A25: Challenge rate | B25: ='AI Summary'!$B$9 -> 1 | D25: G3 | E25: Feature freeze - no new features | F25: 14 | G25: =$B$3+$F25-1 -> 46307 | H25: =COUNTIFS(WBS!$B$5:'WBS'!$B$144,3,WBS!$F$5:'WBS'!$F$144,"<="&$F25,WBS!$L$5:'WBS'!$L$144,"<>Done",WBS!$L$5:'WBS'!$L$144,"<>Deferred") -> 64 | I25: =IF($H25=0,"Cleared",IF($F25<$B$5,"MISSED","Open")) -> Open
A26: AI was wrong (target 8) | B26: ='AI Summary'!$B$10 -> 2 | D26: G4 | E26: Five E2E flows green | F26: 16 | G26: =$B$3+$F26-1 -> 46309 | H26: =COUNTIFS(WBS!$B$5:'WBS'!$B$144,3,WBS!$F$5:'WBS'!$F$144,"<="&$F26,WBS!$L$5:'WBS'!$L$144,"<>Done",WBS!$L$5:'WBS'!$L$144,"<>Deferred") -> 74 | I26: =IF($H26=0,"Cleared",IF($F26<$B$5,"MISSED","Open")) -> Open
A27: Net hours from AI | B27: ='AI Summary'!$B$15 -> 0 | D27: G5 | E27: Documentation complete | F27: 19 | G27: =$B$3+$F27-1 -> 46312 | H27: =COUNTIFS(WBS!$B$5:'WBS'!$B$144,3,WBS!$F$5:'WBS'!$F$144,"<="&$F27,WBS!$L$5:'WBS'!$L$144,"<>Done",WBS!$L$5:'WBS'!$L$144,"<>Deferred") -> 87 | I27: =IF($H27=0,"Cleared",IF($F27<$B$5,"MISSED","Open")) -> Open
D28: G6 | E28: Submission | F28: 21 | G28: =$B$3+$F28-1 -> 46314 | H28: =COUNTIFS(WBS!$B$5:'WBS'!$B$144,3,WBS!$F$5:'WBS'!$F$144,"<="&$F28,WBS!$L$5:'WBS'!$L$144,"<>Done",WBS!$L$5:'WBS'!$L$144,"<>Deferred") -> 94 | I28: =IF($H28=0,"Cleared",IF($F28<$B$5,"MISSED","Open")) -> Open
D31: AI usage evidence — brief §21 coverage
D32: § | E32: What §21 asks for | F32: Evidence lives on | G32: Have | H32: Target | I32: Status
D33: 1 | E33: Which AI tools or agents you used | F33: AI Policy | G33: =COUNTA('AI Policy'!$A$9:$A$13) -> 5 | H33: 5 | I33: =IF($G33>=$H33,"Covered","Need "&($H33-$G33)&" more") -> Covered
D34: 2 | E34: What responsibilities were assigned to them | F34: AI Policy | G34: =COUNTA('AI Policy'!$A$18:$A$27) -> 10 | H34: 10 | I34: =IF($G34>=$H34,"Covered","Need "&($H34-$G34)&" more") -> Covered
D35: 3 | E35: Important prompts or workflows | F35: Prompt Library | G35: =COUNTA('Prompt Library'!$B$5:$B$84) -> 2 | H35: 10 | I35: =IF($G35>=$H35,"Covered","Need "&($H35-$G35)&" more") -> Need 8 more
D36: 4 | E36: How their output was validated | F36: AI Usage Log + AI Policy | G36: =COUNTA('AI Usage Log'!$N$5:$N$204) -> 2 | H36: ='AI Summary'!$B$5 -> 2 | I36: =IF($G36>=$H36,"Covered","Need "&($H36-$G36)&" more") -> Covered
D37: 5 | E37: Examples where AI output was incorrect or insufficient | F37: AI Failures | G37: =COUNTA('AI Failures'!$B$5:$B$44) -> 2 | H37: 8 | I37: =IF($G37>=$H37,"Covered","Need "&($H37-$G37)&" more") -> Need 6 more
D38: 6 | E38: Examples where your own judgment improved the result | F38: AI Usage Log + AI Failures | G38: ='AI Summary'!$B$7+'AI Summary'!$B$8 -> 2 | H38: 8 | I38: =IF($G38>=$H38,"Covered","Need "&($H38-$G38)&" more") -> Need 6 more
D39: 7 | E39: AI implementation you significantly modified, and why | F39: Modified Impl | G39: =COUNTA('Modified Impl'!$B$5:$B$44) -> 1 | H39: 5 | I39: =IF($G39>=$H39,"Covered","Need "&($H39-$G39)&" more") -> Need 4 more
D42: Work packages — titles and subtask progress
D43: WBS | E43: Work package (title) | F43: Phase | G43: Days | H43: Subtasks | I43: Done | J43: % Done
D44: 1.1 | E44: =TRIM(INDEX(WBS!$C$5:$C$144,MATCH($D44,WBS!$A$5:$A$144,0))) -> Brief analysis and gap discovery | F44: =INDEX(WBS!$D$5:$D$144,MATCH($D44,WBS!$A$5:$A$144,0)) -> Discovery | G44: ="D"&INDEX(WBS!$F$5:$F$144,MATCH($D44,WBS!$A$5:$A$144,0))&"-D"&INDEX(WBS!$T$5:$T$144,MATCH($D44,WBS!$A$5:$A$144,0)) -> D1-D2 | H44: =COUNTIFS(WBS!$R$5:$R$144,$D44,WBS!$B$5:$B$144,3) -> 3 | I44: =COUNTIFS(WBS!$R$5:$R$144,$D44,WBS!$B$5:$B$144,3,WBS!$L$5:$L$144,"Done") -> 0 | J44: =INDEX(WBS!$M$5:$M$144,MATCH($D44,WBS!$A$5:$A$144,0)) -> 0
D45: 1.2 | E45: =TRIM(INDEX(WBS!$C$5:$C$144,MATCH($D45,WBS!$A$5:$A$144,0))) -> Stakeholder simulation | F45: =INDEX(WBS!$D$5:$D$144,MATCH($D45,WBS!$A$5:$A$144,0)) -> Discovery | G45: ="D"&INDEX(WBS!$F$5:$F$144,MATCH($D45,WBS!$A$5:$A$144,0))&"-D"&INDEX(WBS!$T$5:$T$144,MATCH($D45,WBS!$A$5:$A$144,0)) -> D1-D3 | H45: =COUNTIFS(WBS!$R$5:$R$144,$D45,WBS!$B$5:$B$144,3) -> 4 | I45: =COUNTIFS(WBS!$R$5:$R$144,$D45,WBS!$B$5:$B$144,3,WBS!$L$5:$L$144,"Done") -> 0 | J45: =INDEX(WBS!$M$5:$M$144,MATCH($D45,WBS!$A$5:$A$144,0)) -> 0
...

Sheet WBS
A1: SmartRail — Work Breakdown Structure
A2: EDIT ONLY the blue columns: Day, Dur, Est h, Act h, Status, Notes. Everything black is a formula. Phase (level 1) and work-package (level 2) rows roll up automatically from their tasks.
A4: WBS | B4: Lvl | C4: Work item | D4: Phase | E4: WS | F4: Day | G4: Start | H4: End | I4: Dur | J4: Est h | K4: Act h | L4: Status | M4: % Done | N4: Gate | O4: Traces | P4: Definition of done | Q4: Notes / blocker | R4: _parent | S4: _root | T4: _endday | U4: _den | V4: _num | W4: _act | X4: _startday | Y4: _l3end
A5: 1 | B5: 1 | C5: Discovery | D5: Discovery | F5: =IFERROR(_xlfn.MINIFS($X$5:$X$144,$S$5:$S$144,$A5,$B$5:$B$144,3),"") -> 1 | G5: =IF($F5="","",Dashboard!$B$3+$F5-1) -> 46294 | H5: =IF($T5="","",Dashboard!$B$3+$T5-1) -> 46296 | I5: =IFERROR($T5-$F5+1,"") -> 3 | J5: =SUMIFS($U$5:$U$144,$S$5:$S$144,$A5,$B$5:$B$144,3) -> 28.5 | K5: =SUMIFS($W$5:$W$144,$S$5:$S$144,$A5,$B$5:$B$144,3) -> 0 | M5: =IFERROR(SUMIFS($V$5:$V$144,$S$5:$S$144,$A5,$B$5:$B$144,3)/SUMIFS($U$5:$U$144,$S$5:$S$144,$A5,$B$5:$B$144,3),0) -> 0.10526316 | T5: =IFERROR(_xlfn.MAXIFS($Y$5:$Y$144,$S$5:$S$144,$A5,$B$5:$B$144,3),"") -> 3
A6: 1.1 | B6: 2 | C6: Brief analysis and gap discovery | D6: Discovery | F6: =IFERROR(_xlfn.MINIFS($X$5:$X$144,$R$5:$R$144,$A6,$B$5:$B$144,3),"") -> 1 | G6: =IF($F6="","",Dashboard!$B$3+$F6-1) -> 46294 | H6: =IF($T6="","",Dashboard!$B$3+$T6-1) -> 46295 | I6: =IFERROR($T6-$F6+1,"") -> 2 | J6: =SUMIFS($U$5:$U$144,$R$5:$R$144,$A6,$B$5:$B$144,3) -> 6 | K6: =SUMIFS($W$5:$W$144,$R$5:$R$144,$A6,$B$5:$B$144,3) -> 0 | M6: =IFERROR(SUMIFS($V$5:$V$144,$R$5:$R$144,$A6,$B$5:$B$144,3)/SUMIFS($U$5:$U$144,$R$5:$R$144,$A6,$B$5:$B$144,3),0) -> 0 | R6: 1 | S6: 1 | T6: =IFERROR(_xlfn.MAXIFS($Y$5:$Y$144,$R$5:$R$144,$A6,$B$5:$B$144,3),"") -> 2
A7: 1.1.1 | B7: 3 | C7: Decompose brief into atomic statements tagged GIVEN / IMPLIED / ABSENT | D7: Discovery | E7: REQ | F7: 1 | G7: =IF($F7="","",Dashboard!$B$3+$F7-1) -> 46294 | H7: =IF($T7="","",Dashboard!$B$3+$T7-1) -> 46294 | I7: 1 | J7: 3 | L7: To do | M7: =IF($L7="Done",1,IF($L7="Doing",0.5,0)) -> 0 | O7: brief all sections | P7: One statement per brief sentence, each tagged | R7: 1.1 | S7: 1 | T7: =$F7+$I7-1 -> 1 | U7: =IF($L7="Deferred",0,$J7) -> 3 | V7: =IF($L7="Deferred",0,$J7*$M7) -> 0 | W7: =IF($L7="Deferred",0,N($K7)) -> 0 | X7: =$F7 -> 1 | Y7: =$T7 -> 1
A8: 1.1.2 | B8: 3 | C8: Convert plan section 6 findings into REQ / ASM / EDG / OQ entries | D8: Discovery | E8: REQ | F8: 2 | G8: =IF($F8="","",Dashboard!$B$3+$F8-1) -> 46295 | H8: =IF($T8="","",Dashboard!$B$3+$T8-1) -> 46295 | I8: 1 | J8: 2 | L8: To do | M8: =IF($L8="Done",1,IF($L8="Doing",0.5,0)) -> 0 | O8: plan.md S6 | P8: All 59 findings carry an id and a type | R8: 1.1 | S8: 1 | T8: =$F8+$I8-1 -> 2 | U8: =IF($L8="Deferred",0,$J8) -> 2 | V8: =IF($L8="Deferred",0,$J8*$M8) -> 0 | W8: =IF($L8="Deferred",0,N($K8)) -> 0 | X8: =$F8 -> 2 | Y8: =$T8 -> 2
A9: 1.1.3 | B9: 3 | C9: Assumptions register with rationale | D9: Discovery | E9: REQ | F9: 2 | G9: =IF($F9="","",Dashboard!$B$3+$F9-1) -> 46295 | H9: =IF($T9="","",Dashboard!$B$3+$T9-1) -> 46295 | I9: 1 | J9: 1 | L9: To do | M9: =IF($L9="Done",1,IF($L9="Doing",0.5,0)) -> 0 | P9: Every ASM states what breaks if it is wrong | R9: 1.1 | S9: 1 | T9: =$F9+$I9-1 -> 2 | U9: =IF($L9="Deferred",0,$J9) -> 1 | V9: =IF($L9="Deferred",0,$J9*$M9) -> 0 | W9: =IF($L9="Deferred",0,N($K9)) -> 0 | X9: =$F9 -> 2 | Y9: =$T9 -> 2
A10: 1.2 | B10: 2 | C10: Stakeholder simulation | D10: Discovery | F10: =IFERROR(_xlfn.MINIFS($X$5:$X$144,$R$5:$R$144,$A10,$B$5:$B$144,3),"") -> 1 | G10: =IF($F10="","",Dashboard!$B$3+$F10-1) -> 46294 | H10: =IF($T10="","",Dashboard!$B$3+$T10-1) -> 46296 | I10: =IFERROR($T10-$F10+1,"") -> 3 | J10: =SUMIFS($U$5:$U$144,$R$5:$R$144,$A10,$B$5:$B$144,3) -> 10 | K10: =SUMIFS($W$5:$W$144,$R$5:$R$144,$A10,$B$5:$B$144,3) -> 0 | M10: =IFERROR(SUMIFS($V$5:$V$144,$R$5:$R$144,$A10,$B$5:$B$144,3)/SUMIFS($U$5:$U$144,$R$5:$R$144,$A10,$B$5:$B$144,3),0) -> 0 | R10: 1 | S10: 1 | T10: =IFERROR(_xlfn.MAXIFS($Y$5:$Y$144,$R$5:$R$144,$A10,$B$5:$B$144,3),"") -> 3
A11: 1.2.1 | B11: 3 | C11: Persona interviews 1-6 commuter, traveller, impaired passenger, driver, station manager, controller | D11: Discovery | E11: REQ | F11: 1 | G11: =IF($F11="","",Dashboard!$B$3+$F11-1) -> 46294 | H11: =IF($T11="","",Dashboard!$B$3+$T11-1) -> 46294 | I11: 1 | J11: 3 | L11: To do | M11: =IF($L11="Done",1,IF($L11="Doing",0.5,0)) -> 0 | P11: Transcript plus extracted requirements per persona | R11: 1.2 | S11: 1 | T11: =$F11+$I11-1 -> 1 | U11: =IF($L11="Deferred",0,$J11) -> 3 | V11: =IF($L11="Deferred",0,$J11*$M11) -> 0 | W11: =IF($L11="Deferred",0,N($K11)) -> 0 | X11: =$F11 -> 1 | Y11: =$T11 -> 1
A12: 1.2.2 | B12: 3 | C12: Persona interviews 7-12 CS agent, catering ops, security, QA, accessibility, DPO | D12: Discovery | E12: REQ | F12: 2 | G12: =IF($F12="","",Dashboard!$B$3+$F12-1) -> 46295 | H12: =IF($T12="","",Dashboard!$B$3+$T12-1) -> 46295 | I12: 1 | J12: 3 | L12: To do | M12: =IF($L12="Done",1,IF($L12="Doing",0.5,0)) -> 0 | P12: Transcript plus extracted requirements per persona | R12: 1.2 | S12: 1 | T12: =$F12+$I12-1 -> 2 | U12: =IF($L12="Deferred",0,$J12) -> 3 | V12: =IF($L12="Deferred",0,$J12*$M12) -> 0 | W12: =IF($L12="Deferred",0,N($K12)) -> 0 | X12: =$F12 -> 2 | Y12: =$T12 -> 2
A13: 1.2.3 | B13: 3 | C13: Adversarial pass - what would make each persona distrust the system | D13: Discovery | E13: REQ | F13: 2 | G13: =IF($F13="","",Dashboard!$B$3+$F13-1) -> 46295 | H13: =IF($T13="","",Dashboard!$B$3+$T13-1) -> 46295 | I13: 1 | J13: 2 | L13: To do | M13: =IF($L13="Done",1,IF($L13="Doing",0.5,0)) -> 0 | P13: Failure requirements captured as EDG entries | R13: 1.2 | S13: 1 | T13: =$F13+$I13-1 -> 2 | U13: =IF($L13="Deferred",0,$J13) -> 2 | V13: =IF($L13="Deferred",0,$J13*$M13) -> 0 | W13: =IF($L13="Deferred",0,N($K13)) -> 0 | X13: =$F13 -> 2 | Y13: =$T13 -> 2
A14: 1.2.4 | B14: 3 | C14: Reconcile conflicts and record the losing option in writing | D14: Discovery | E14: REQ | F14: 3 | G14: =IF($F14="","",Dashboard!$B$3+$F14-1) -> 46296 | H14: =IF($T14="","",Dashboard!$B$3+$T14-1) -> 46296 | I14: 1 | J14: 2 | L14: To do | M14: =IF($L14="Done",1,IF($L14="Doing",0.5,0)) -> 0 | P14: No averaged requirements - conflicts resolved by me, both sides recorded | R14: 1.2 | S14: 1 | T14: =$F14+$I14-1 -> 3 | U14: =IF($L14="Deferred",0,$J14) -> 2 | V14: =IF($L14="Deferred",0,$J14*$M14) -> 0 | W14: =IF($L14="Deferred",0,N($K14)) -> 0 | X14: =$F14 -> 3 | Y14: =$T14 -> 3
A15: 1.3 | B15: 2 | C15: Requirement engineering | D15: Discovery | F15: =IFERROR(_xlfn.MINIFS($X$5:$X$144,$R$5:$R$144,$A15,$B$5:$B$144,3),"") -> 2 | G15: =IF($F15="","",Dashboard!$B$3+$F15-1) -> 46295 | H15: =IF($T15="","",Dashboard!$B$3+$T15-1) -> 46296 | I15: =IFERROR($T15-$F15+1,"") -> 2 | J15: =SUMIFS($U$5:$U$144,$R$5:$R$144,$A15,$B$5:$B$144,3) -> 7.5 | K15: =SUMIFS($W$5:$W$144,$R$5:$R$144,$A15,$B$5:$B$144,3) -> 0 | M15: =IFERROR(SUMIFS($V$5:$V$144,$R$5:$R$144,$A15,$B$5:$B$144,3)/SUMIFS($U$5:$U$144,$R$5:$R$144,$A15,$B$5:$B$144,3),0) -> 0 | R15: 1 | S15: 1 | T15: =IFERROR(_xlfn.MAXIFS($Y$5:$Y$144,$R$5:$R$144,$A15,$B$5:$B$144,3),"") -> 3
A16: 1.3.1 | B16: 3 | C16: Edge case catalogue target 40 plus entries | D16: Discovery | E16: REQ | F16: 2 | G16: =IF($F16="","",Dashboard!$B$3+$F16-1) -> 46295 | H16: =IF($T16="","",Dashboard!$B$3+$T16-1) -> 46295 | I16: 1 | J16: 2 | L16: To do | M16: =IF($L16="Done",1,IF($L16="Doing",0.5,0)) -> 0 | P16: EDG ids assigned | R16: 1.3 | S16: 1 | T16: =$F16+$I16-1 -> 2 | U16: =IF($L16="Deferred",0,$J16) -> 2 | V16: =IF($L16="Deferred",0,$J16*$M16) -> 0 | W16: =IF($L16="Deferred",0,N($K16)) -> 0 | X16: =$F16 -> 2 | Y16: =$T16 -> 2
A17: 1.3.2 | B17: 3 | C17: Prioritise MoSCoW plus risk times value score | D17: Discovery | E17: REQ | F17: 3 | G17: =IF($F17="","",Dashboard!$B$3+$F17-1) -> 46296 | H17: =IF($T17="","",Dashboard!$B$3+$T17-1) -> 46296 | I17: 1 | J17: 1.5 | L17: To do | M17: =IF($L17="Done",1,IF($L17="Doing",0.5,0)) -> 0 | P17: Every Must maps to one of the five E2E flows | R17: 1.3 | S17: 1 | T17: =$F17+$I17-1 -> 3 | U17: =IF($L17="Deferred",0,$J17) -> 1.5 | V17: =IF($L17="Deferred",0,$J17*$M17) -> 0 | W17: =IF($L17="Deferred",0,N($K17)) -> 0 | X17: =$F17 -> 3 | Y17: =$T17 -> 3
A18: 1.3.3 | B18: 3 | C18: User stories and acceptance criteria for all Must items | D18: Discovery | E18: REQ | F18: 3 | G18: =IF($F18="","",Dashboard!$B$3+$F18-1) -> 46296 | H18: =IF($T18="","",Dashboard!$B$3+$T18-1) -> 46296 | I18: 1 | J18: 3 | L18: To do | M18: =IF($L18="Done",1,IF($L18="Doing",0.5,0)) -> 0 | P18: Given/When/Then for each AC | R18: 1.3 | S18: 1 | T18: =$F18+$I18-1 -> 3 | U18: =IF($L18="Deferred",0,$J18) -> 3 | V18: =IF($L18="Deferred",0,$J18*$M18) -> 0 | W18: =IF($L18="Deferred",0,N($K18)) -> 0 | X18: =$F18 -> 3 | Y18: =$T18 -> 3
A19: 1.3.4 | B19: 3 | C19: Traceability matrix skeleton REQ to US to AC to test | D19: Discovery | E19: REQ | F19: 3 | G19: =IF($F19="","",Dashboard!$B$3+$F19-1) -> 46296 | H19: =IF($T19="","",Dashboard!$B$3+$T19-1) -> 46296 | I19: 1 | J19: 1 | L19: To do | M19: =IF($L19="Done",1,IF($L19="Doing",0.5,0)) -> 0 | P19: One row per requirement, test column present but empty | R19: 1.3 | S19: 1 | T19: =$F19+$I19-1 -> 3 | U19: =IF($L19="Deferred",0,$J19) -> 1 | V19: =IF($L19="Deferred",0,$J19*$M19) -> 0 | W19: =IF($L19="Deferred",0,N($K19)) -> 0 | X19: =$F19 -> 3 | Y19: =$T19 -> 3
A20: 1.4 | B20: 2 | C20: Scope control | D20: Discovery | F20: =IFERROR(_xlfn.MINIFS($X$5:$X$144,$R$5:$R$144,$A20,$B$5:$B$144,3),"") -> 3 | G20: =IF($F20="","",Dashboard!$B$3+$F20-1) -> 46296 | H20: =IF($T20="","",Dashboard!$B$3+$T20-1) -> 46296 | I20: =IFERROR($T20-$F20+1,"") -> 1 | J20: =SUMIFS($U$5:$U$144,$R$5:$R$144,$A20,$B$5:$B$144,3) -> 1 | K20: =SUMIFS($W$5:$W$144,$R$5:$R$144,$A20,$B$5:$B$144,3) -> 0 | M20: =IFERROR(SUMIFS($V$5:$V$144,$R$5:$R$144,$A20,$B$5:$B$144,3)/SUMIFS($U$5:$U$144,$R$5:$R$144,$A20,$B$5:$B$144,3),0) -> 0 | R20: 1 | S20: 1 | T20: =IFERROR(_xlfn.MAXIFS($Y$5:$Y$144,$R$5:$R$144,$A20,$B$5:$B$144,3),"") -> 3
A21: 1.4.1 | B21: 3 | C21: Send open questions OQ-01 to OQ-08 to assessors | D21: Discovery | E21: REQ | F21: 3 | G21: =IF($F21="","",Dashboard!$B$3+$F21-1) -> 46296 | H21: =IF($T21="","",Dashboard!$B$3+$T21-1) -> 46296 | I21: 1 | J21: 0.5 | L21: To do | M21: =IF($L21="Done",1,IF($L21="Doing",0.5,0)) -> 0 | O21: plan.md S20 | P21: Sent, with fallback assumption recorded for each | R21: 1.4 | S21: 1 | T21: =$F21+$I21-1 -> 3 | U21: =IF($L21="Deferred",0,$J21) -> 0.5 | V21: =IF($L21="Deferred",0,$J21*$M21) -> 0 | W21: =IF($L21="Deferred",0,N($K21)) -> 0 | X21: =$F21 -> 3 | Y21: =$T21 -> 3
A22: 1.4.2 | B22: 3 | C22: Baseline scope and freeze requirements | D22: Discovery | E22: REQ | F22: 3 | G22: =IF($F22="","",Dashboard!$B$3+$F22-1) -> 46296 | H22: =IF($T22="","",Dashboard!$B$3+$T22-1) -> 46296 | I22: 1 | J22: 0.5 | L22: To do | M22: =IF($L22="Done",1,IF($L22="Doing",0.5,0)) -> 0 | N22: G1 | P22: Scope signed off by me, change log opened | R22: 1.4 | S22: 1 | T22: =$F22+$I22-1 -> 3 | U22: =IF($L22="Deferred",0,$J22) -> 0.5 | V22: =IF($L22="Deferred",0,$J22*$M22) -> 0 | W22: =IF($L22="Deferred",0,N($K22)) -> 0 | X22: =$F22 -> 3 | Y22: =$T22 -> 3
A23: 1.5 | B23: 2 | C23: Project setup | D23: Discovery | F23: =IFERROR(_xlfn.MINIFS($X$5:$X$144,$R$5:$R$144,$A23,$B$5:$B$144,3),"") -> 1 | G23: =IF($F23="","",Dashboard!$B$3+$F23-1) -> 46294 | H23: =IF($T23="","",Dashboard!$B$3+$T23-1) -> 46294 | I23: =IFERROR($T23-$F23+1,"") -> 1 | J23: =SUMIFS($U$5:$U$144,$R$5:$R$144,$A23,$B$5:$B$144,3) -> 4 | K23: =SUMIFS($W$5:$W$144,$R$5:$R$144,$A23,$B$5:$B$144,3) -> 0 | M23: =IFERROR(SUMIFS($V$5:$V$144,$R$5:$R$144,$A23,$B$5:$B$144,3)/SUMIFS($U$5:$U$144,$R$5:$R$144,$A23,$B$5:$B$144,3),0) -> 0.75 | R23: 1 | S23: 1 | T23: =IFERROR(_xlfn.MAXIFS($Y$5:$Y$144,$R$5:$R$144,$A23,$B$5:$B$144,3),"") -> 1
A24: 1.5.1 | B24: 3 | C24: Author master delivery plan | D24: Discovery | E24: DOC | F24: 1 | G24: =IF($F24="","",Dashboard!$B$3+$F24-1) -> 46294 | H24: =IF($T24="","",Dashboard!$B$3+$T24-1) -> 46294 | I24: 1 | J24: 2 | L24: Done | M24: =IF($L24="Done",1,IF($L24="Doing",0.5,0)) -> 1 | O24: plan.md | P24: Stack decided, scope fixed, 59 gaps registered | R24: 1.5 | S24: 1 | T24: =$F24+$I24-1 -> 1 | U24: =IF($L24="Deferred",0,$J24) -> 2 | V24: =IF($L24="Deferred",0,$J24*$M24) -> 2 | W24: =IF($L24="Deferred",0,N($K24)) -> 0 | X24: =$F24 -> 1 | Y24: =$T24 -> 1
A25: 1.5.2 | B25: 3 | C25: Create repo and docs folder skeleton | D25: Discovery | E25: ARCH | F25: 1 | G25: =IF($F25="","",Dashboard!$B$3+$F25-1) -> 46294 | H25: =IF($T25="","",Dashboard!$B$3+$T25-1) -> 46294 | I25: 1 | J25: 1 | L25: To do | M25: =IF($L25="Done",1,IF($L25="Doing",0.5,0)) -> 0 | P25: docs/00 to 06 present, git initialised | R25: 1.5 | S25: 1 | T25: =$F25+$I25-1 -> 1 | U25: =IF($L25="Deferred",0,$J25) -> 1 | V25: =IF($L25="Deferred",0,$J25*$M25) -> 0 | W25: =IF($L25="Deferred",0,N($K25)) -> 0 | X25: =$F25 -> 1 | Y25: =$T25 -> 1
A26: 1.5.3 | B26: 3 | C26: Set up tracking workbook and git commit template | D26: Discovery | E26: DOC | F26: 1 | G26: =IF($F26="","",Dashboard!$B$3+$F26-1) -> 46294 | H26: =IF($T26="","",Dashboard!$B$3+$T26-1) -> 46294 | I26: 1 | J26: 1 | L26: Done | M26: =IF($L26="Done",1,IF($L26="Doing",0.5,0)) -> 1 | P26: Workbook live, commit.template configured | R26: 1.5 | S26: 1 | T26: =$F26+$I26-1 -> 1 | U26: =IF($L26="Deferred",0,$J26) -> 1 | V26: =IF($L26="Deferred",0,$J26*$M26) -> 1 | W26: =IF($L26="Deferred",0,N($K26)) -> 0 | X26: =$F26 -> 1 | Y26: =$T26 -> 1
A27: 2 | B27: 1 | C27: Design and Decide | D27: Design and Decide | F27: =IFERROR(_xlfn.MINIFS($X$5:$X$144,$S$5:$S$144,$A27,$B$5:$B$144,3),"") -> 4 | G27: =IF($F27="","",Dashboard!$B$3+$F27-1) -> 46297 | H27: =IF($T27="","",Dashboard!$B$3+$T27-1) -> 46298 | I27: =IFERROR($T27-$F27+1,"") -> 2 | J27: =SUMIFS($U$5:$U$144,$S$5:$S$144,$A27,$B$5:$B$144,3) -> 16 | K27: =SUMIFS($W$5:$W$144,$S$5:$S$144,$A27,$B$5:$B$144,3) -> 0 | M27: =IFERROR(SUMIFS($V$5:$V$144,$S$5:$S$144,$A27,$B$5:$B$144,3)/SUMIFS($U$5:$U$144,$S$5:$S$144,$A27,$B$5:$B$144,3),0) -> 0 | T27: =IFERROR(_xlfn.MAXIFS($Y$5:$Y$144,$S$5:$S$144,$A27,$B$5:$B$144,3),"") -> 5
A28: 2.1 | B28: 2 | C28: Domain design | D28: Design and Decide | F28: =IFERROR(_xlfn.MINIFS($X$5:$X$144,$R$5:$R$144,$A28,$B$5:$B$144,3),"") -> 4 | G28: =IF($F28="","",Dashboard!$B$3+$F28-1) -> 46297 | H28: =IF($T28="","",Dashboard!$B$3+$T28-1) -> 46297 | I28: =IFERROR($T28-$F28+1,"") -> 1 | J28: =SUMIFS($U$5:$U$144,$R$5:$R$144,$A28,$B$5:$B$144,3) -> 5 | K28: =SUMIFS($W$5:$W$144,$R$5:$R$144,$A28,$B$5:$B$144,3) -> 0 | M28: =IFERROR(SUMIFS($V$5:$V$144,$R$5:$R$144,$A28,$B$5:$B$144,3)/SUMIFS($U$5:$U$144,$R$5:$R$144,$A28,$B$5:$B$144,3),0) -> 0 | R28: 2 | S28: 2 | T28: =IFERROR(_xlfn.MAXIFS($Y$5:$Y$144,$R$5:$R$144,$A28,$B$5:$B$144,3),"") -> 4
A29: 2.1.1 | B29: 3 | C29: Domain model - network, timetable versions, service calendars | D29: Design and Decide | E29: ARCH | F29: 4 | G29: =IF($F29="","",Dashboard!$B$3+$F29-1) -> 46297 | H29: =IF($T29="","",Dashboard!$B$3+$T29-1) -> 46297 | I29: 1 | J29: 3 | L29: To do | M29: =IF($L29="Done",1,IF($L29="Doing",0.5,0)) -> 0 | P29: Service date separated from calendar date | R29: 2.1 | S29: 2 | T29: =$F29+$I29-1 -> 4 | U29: =IF($L29="Deferred",0,$J29) -> 3 | V29: =IF($L29="Deferred",0,$J29*$M29) -> 0 | W29: =IF($L29="Deferred",0,N($K29)) -> 0 | X29: =$F29 -> 4 | Y29: =$T29 -> 4
A30: 2.1.2 | B30: 3 | C30: Journey state machine including Unknown and TerminatedShort | D30: Design and Decide | E30: ARCH | F30: 4 | G30: =IF($F30="","",Dashboard!$B$3+$F30-1) -> 46297 | H30: =IF($T30="","",Dashboard!$B$3+$T30-1) -> 46297 | I30: 1 | J30: 2 | L30: To do | M30: =IF($L30="Done",1,IF($L30="Doing",0.5,0)) -> 0 | P30: Diagram plus the invariant list that becomes unit tests | R30: 2.1 | S30: 2 | T30: =$F30+$I30-1 -> 4 | U30: =IF($L30="Deferred",0,$J30) -> 2 | V30: =IF($L30="Deferred",0,$J30*$M30) -> 0 | W30: =IF($L30="Deferred",0,N($K30)) -> 0 | X30: =$F30 -> 4 | Y30: =$T30 -> 4
A31: 2.2 | B31: 2 | C31: Architecture decisions | D31: Design and Decide | F31: =IFERROR(_xlfn.MINIFS($X$5:$X$144,$R$5:$R$144,$A31,$B$5:$B$144,3),"") -> 4 | G31: =IF($F31="","",Dashboard!$B$3+$F31-1) -> 46297 | H31: =IF($T31="","",Dashboard!$B$3+$T31-1) -> 46297 | I31: =IFERROR($T31-$F31+1,"") -> 1 | J31: =SUMIFS($U$5:$U$144,$R$5:$R$144,$A31,$B$5:$B$144,3) -> 3 | K31: =SUMIFS($W$5:$W$144,$R$5:$R$144,$A31,$B$5:$B$144,3) -> 0 | M31: =IFERROR(SUMIFS($V$5:$V$144,$R$5:$R$144,$A31,$B$5:$B$144,3)/SUMIFS($U$5:$U$144,$R$5:$R$144,$A31,$B$5:$B$144,3),0) -> 0 | R31: 2 | S31: 2 | T31: =IFERROR(_xlfn.MAXIFS($Y$5:$Y$144,$R$5:$R$144,$A31,$B$5:$B$144,3),"") -> 4
A32: 2.2.1 | B32: 3 | C32: Write ADR 0001 to 0008 | D32: Design and Decide | E32: ARCH | F32: 4 | G32: =IF($F32="","",Dashboard!$B$3+$F32-1) -> 46297 | H32: =IF($T32="","",Dashboard!$B$3+$T32-1) -> 46297 | I32: 1 | J32: 2 | L32: To do | M32: =IF($L32="Done",1,IF($L32="Doing",0.5,0)) -> 0 | P32: Each ADR names the rejected option and why | R32: 2.2 | S32: 2 | T32: =$F32+$I32-1 -> 4 | U32: =IF($L32="Deferred",0,$J32) -> 2 | V32: =IF($L32="Deferred",0,$J32*$M32) -> 0 | W32: =IF($L32="Deferred",0,N($K32)) -> 0 | X32: =$F32 -> 4 | Y32: =$T32 -> 4
A33: 2.2.2 | B33: 3 | C33: C4 context and container diagrams | D33: Design and Decide | E33: ARCH | F33: 4 | G33: =IF($F33="","",Dashboard!$B$3+$F33-1) -> 46297 | H33: =IF($T33="","",Dashboard!$B$3+$T33-1) -> 46297 | I33: 1 | J33: 1 | L33: To do | M33: =IF($L33="Done",1,IF($L33="Doing",0.5,0)) -> 0 | P33: Two levels, committed as source | R33: 2.2 | S33: 2 | T33: =$F33+$I33-1 -> 4 | U33: =IF($L33="Deferred",0,$J33) -> 1 | V33: =IF($L33="Deferred",0,$J33*$M33) -> 0 | W33: =IF($L33="Deferred",0,N($K33)) -> 0 | X33: =$F33 -> 4 | Y33: =$T33 -> 4
A34: 2.3 | B34: 2 | C34: Security design | D34: Design and Decide | F34: =IFERROR(_xlfn.MINIFS($X$5:$X$144,$R$5:$R$144,$A34,$B$5:$B$144,3),"") -> 5 | G34: =IF($F34="","",Dashboard!$B$3+$F34-1) -> 46298 | H34: =IF($T34="","",Dashboard!$B$3+$T34-1) -> 46298 | I34: =IFERROR($T34-$F34+1,"") -> 1 | J34: =SUMIFS($U$5:$U$144,$R$5:$R$144,$A34,$B$5:$B$144,3) -> 5 | K34: =SUMIFS($W$5:$W$144,$R$5:$R$144,$A34,$B$5:$B$144,3) -> 0 | M34: =IFERROR(SUMIFS($V$5:$V$144,$R$5:$R$144,$A34,$B$5:$B$144,3)/SUMIFS($U$5:$U$144,$R$5:$R$144,$A34,$B$5:$B$144,3),0) -> 0 | R34: 2 | S34: 2 | T34: =IFERROR(_xlfn.MAXIFS($Y$5:$Y$144,$R$5:$R$144,$A34,$B$5:$B$144,3),"") -> 5
A35: 2.3.1 | B35: 3 | C35: STRIDE threat model per trust boundary | D35: Design and Decide | E35: SEC | F35: 5 | G35: =IF($F35="","",Dashboard!$B$3+$F35-1) -> 46298 | H35: =IF($T35="","",Dashboard!$B$3+$T35-1) -> 46298 | I35: 1 | J35: 2.5 | L35: To do | M35: =IF($L35="Done",1,IF($L35="Doing",0.5,0)) -> 0 | P35: Five boundaries covered, each risk mapped to a control | R35: 2.3 | S35: 2 | T35: =$F35+$I35-1 -> 5 | U35: =IF($L35="Deferred",0,$J35) -> 2.5 | V35: =IF($L35="Deferred",0,$J35*$M35) -> 0 | W35: =IF($L35="Deferred",0,N($K35)) -> 0 | X35: =$F35 -> 5 | Y35: =$T35 -> 5
A36: 2.3.2 | B36: 3 | C36: Permission matrix for ten roles with scoped permissions | D36: Design and Decide | E36: SEC | F36: 5 | G36: =IF($F36="","",Dashboard!$B$3+$F36-1) -> 46298 | H36: =IF($T36="","",Dashboard!$B$3+$T36-1) -> 46298 | I36: 1 | J36: 1.5 | L36: To do | M36: =IF($L36="Done",1,IF($L36="Doing",0.5,0)) -> 0 | P36: Every cell has a planned positive and negative test | R36: 2.3 | S36: 2 | T36: =$F36+$I36-1 -> 5 | U36: =IF($L36="Deferred",0,$J36) -> 1.5 | V36: =IF($L36="Deferred",0,$J36*$M36) -> 0 | W36: =IF($L36="Deferred",0,N($K36)) -> 0 | X36: =$F36 -> 5 | Y36: =$T36 -> 5
A37: 2.3.3 | B37: 3 | C37: Data classification and retention schedule | D37: Design and Decide | E37: SEC | F37: 5 | G37: =IF($F37="","",Dashboard!$B$3+$F37-1) -> 46298 | H37: =IF($T37="","",Dashboard!$B$3+$T37-1) -> 46298 | I37: 1 | J37: 1 | L37: To do | M37: =IF($L37="Done",1,IF($L37="Doing",0.5,0)) -> 0 | P37: Four classes, owner, retention and log-redaction rule each | R37: 2.3 | S37: 2 | T37: =$F37+$I37-1 -> 5 | U37: =IF($L37="Deferred",0,$J37) -> 1 | V37: =IF($L37="Deferred",0,$J37*$M37) -> 0 | W37: =IF($L37="Deferred",0,N($K37)) -> 0 | X37: =$F37 -> 5 | Y37: =$T37 -> 5
A38: 2.4 | B38: 2 | C38: Design system | D38: Design and Decide | F38: =IFERROR(_xlfn.MINIFS($X$5:$X$144,$R$5:$R$144,$A38,$B$5:$B$144,3),"") -> 5 | G38: =IF($F38="","",Dashboard!$B$3+$F38-1) -> 46298 | H38: =IF($T38="","",Dashboard!$B$3+$T38-1) -> 46298 | I38: =IFERROR($T38-$F38+1,"") -> 1 | J38: =SUMIFS($U$5:$U$144,$R$5:$R$144,$A38,$B$5:$B$144,3) -> 3 | K38: =SUMIFS($W$5:$W$144,$R$5:$R$144,$A38,$B$5:$B$144,3) -> 0 | M38: =IFERROR(SUMIFS($V$5:$V$144,$R$5:$R$144,$A38,$B$5:$B$144,3)/SUMIFS($U$5:$U$144,$R$5:$R$144,$A38,$B$5:$B$144,3),0) -> 0 | R38: 2 | S38: 2 | T38: =IFERROR(_xlfn.MAXIFS($Y$5:$Y$144,$R$5:$R$144,$A38,$B$5:$B$144,3),"") -> 5
A39: 2.4.1 | B39: 3 | C39: Design tokens v1 - colour, status semantics, three type scales | D39: Design and Decide | E39: UX | F39: 5 | G39: =IF($F39="","",Dashboard!$B$3+$F39-1) -> 46298 | H39: =IF($T39="","",Dashboard!$B$3+$T39-1) -> 46298 | I39: 1 | J39: 2 | L39: To do | M39: =IF($L39="Done",1,IF($L39="Doing",0.5,0)) -> 0 | P39: Status never colour-only; contrast verified | R39: 2.4 | S39: 2 | T39: =$F39+$I39-1 -> 5 | U39: =IF($L39="Deferred",0,$J39) -> 2 | V39: =IF($L39="Deferred",0,$J39*$M39) -> 0 | W39: =IF($L39="Deferred",0,N($K39)) -> 0 | X39: =$F39 -> 5 | Y39: =$T39 -> 5
A40: 2.4.2 | B40: 3 | C40: Wireframe the six demo-critical screens | D40: Design and Decide | E40: UX | F40: 5 | G40: =IF($F40="","",Dashboard!$B$3+$F40-1) -> 46298 | H40: =IF($T40="","",Dashboard!$B$3+$T40-1) -> 46298 | I40: 1 | J40: 1 | L40: To do | M40: =IF($L40="Done",1,IF($L40="Doing",0.5,0)) -> 0 | P40: Includes stale and offline states | R40: 2.4 | S40: 2 | T40: =$F40+$I40-1 -> 5 | U40: =IF($L40="Deferred",0,$J40) -> 1 | V40: =IF($L40="Deferred",0,$J40*$M40) -> 0 | W40: =IF($L40="Deferred",0,N($K40)) -> 0 | X40: =$F40 -> 5 | Y40: =$T40 -> 5
A41: 3 | B41: 1 | C41: Backend Spine | D41: Backend Spine | F41: =IFERROR(_xlfn.MINIFS($X$5:$X$144,$S$5:$S$144,$A41,$B$5:$B$144,3),"") -> 6 | G41: =IF($F41="","",Dashboard!$B$3+$F41-1) -> 46299 | H41: =IF($T41="","",Dashboard!$B$3+$T41-1) -> 46300 | I41: =IFERROR($T41-$F41+1,"") -> 2 | J41: =SUMIFS($U$5:$U$144,$S$5:$S$144,$A41,$B$5:$B$144,3) -> 17 | K41: =SUMIFS($W$5:$W$144,$S$5:$S$144,$A41,$B$5:$B$144,3) -> 0 | M41: =IFERROR(SUMIFS($V$5:$V$144,$S$5:$S$144,$A41,$B$5:$B$144,3)/SUMIFS($U$5:$U$144,$S$5:$S$144,$A41,$B$5:$B$144,3),0) -> 0 | T41: =IFERROR(_xlfn.MAXIFS($Y$5:$Y$144,$S$5:$S$144,$A41,$B$5:$B$144,3),"") -> 7
...

Sheet Gantt
A1: SmartRail — Gantt
A2: Fully generated from the WBS sheet. Nothing to edit here. Bars: blue = planned, amber = in progress, green = done, red = blocked.
F3: =Dashboard!$B$3+1-1 -> 46294 | G3: =Dashboard!$B$3+2-1 -> 46295 | H3: =Dashboard!$B$3+3-1 -> 46296 | I3: =Dashboard!$B$3+4-1 -> 46297 | J3: =Dashboard!$B$3+5-1 -> 46298 | K3: =Dashboard!$B$3+6-1 -> 46299 | L3: =Dashboard!$B$3+7-1 -> 46300 | M3: =Dashboard!$B$3+8-1 -> 46301 | N3: =Dashboard!$B$3+9-1 -> 46302 | O3: =Dashboard!$B$3+10-1 -> 46303 | P3: =Dashboard!$B$3+11-1 -> 46304 | Q3: =Dashboard!$B$3+12-1 -> 46305 | R3: =Dashboard!$B$3+13-1 -> 46306 | S3: =Dashboard!$B$3+14-1 -> 46307 | T3: =Dashboard!$B$3+15-1 -> 46308 | U3: =Dashboard!$B$3+16-1 -> 46309 | V3: =Dashboard!$B$3+17-1 -> 46310 | W3: =Dashboard!$B$3+18-1 -> 46311 | X3: =Dashboard!$B$3+19-1 -> 46312 | Y3: =Dashboard!$B$3+20-1 -> 46313 | Z3: =Dashboard!$B$3+21-1 -> 46314
A4: WBS | B4: Work item | C4: WS | D4: Est h | E4: % Done | F4: D1 | G4: D2 | H4: D3 | I4: D4 | J4: D5 | K4: D6 | L4: D7 | M4: D8 | N4: D9 | O4: D10 | P4: D11 | Q4: D12 | R4: D13 | S4: D14 | T4: D15 | U4: D16 | V4: D17 | W4: D18 | X4: D19 | Y4: D20 | Z4: D21
A5: =WBS!$A5 -> 1 | B5: =WBS!$C5 -> Discovery | C5: =IF(WBS!$E5="","",WBS!$E5) | D5: =WBS!$J5 -> 28.5 | E5: =WBS!$M5 -> 0.10526316 | F5: =IF(OR(WBS!$F5="",WBS!$T5=""),"",IF(AND(1>=WBS!$F5,1<=WBS!$T5),IF(WBS!$L5="Done",3,IF(WBS!$L5="Doing",2,IF(WBS!$L5="Blocked",4,IF(WBS!$L5="Deferred",5,1)))),"")) -> 1 | G5: =IF(OR(WBS!$F5="",WBS!$T5=""),"",IF(AND(2>=WBS!$F5,2<=WBS!$T5),IF(WBS!$L5="Done",3,IF(WBS!$L5="Doing",2,IF(WBS!$L5="Blocked",4,IF(WBS!$L5="Deferred",5,1)))),"")) -> 1 | H5: =IF(OR(WBS!$F5="",WBS!$T5=""),"",IF(AND(3>=WBS!$F5,3<=WBS!$T5),IF(WBS!$L5="Done",3,IF(WBS!$L5="Doing",2,IF(WBS!$L5="Blocked",4,IF(WBS!$L5="Deferred",5,1)))),"")) -> 1 | I5: =IF(OR(WBS!$F5="",WBS!$T5=""),"",IF(AND(4>=WBS!$F5,4<=WBS!$T5),IF(WBS!$L5="Done",3,IF(WBS!$L5="Doing",2,IF(WBS!$L5="Blocked",4,IF(WBS!$L5="Deferred",5,1)))),"")) | J5: =IF(OR(WBS!$F5="",WBS!$T5=""),"",IF(AND(5>=WBS!$F5,5<=WBS!$T5),IF(WBS!$L5="Done",3,IF(WBS!$L5="Doing",2,IF(WBS!$L5="Blocked",4,IF(WBS!$L5="Deferred",5,1)))),"")) | K5: =IF(OR(WBS!$F5="",WBS!$T5=""),"",IF(AND(6>=WBS!$F5,6<=WBS!$T5),IF(WBS!$L5="Done",3,IF(WBS!$L5="Doing",2,IF(WBS!$L5="Blocked",4,IF(WBS!$L5="Deferred",5,1)))),"")) | L5: =IF(OR(WBS!$F5="",WBS!$T5=""),"",IF(AND(7>=WBS!$F5,7<=WBS!$T5),IF(WBS!$L5="Done",3,IF(WBS!$L5="Doing",2,IF(WBS!$L5="Blocked",4,IF(WBS!$L5="Deferred",5,1)))),"")) | M5: =IF(OR(WBS!$F5="",WBS!$T5=""),"",IF(AND(8>=WBS!$F5,8<=WBS!$T5),IF(WBS!$L5="Done",3,IF(WBS!$L5="Doing",2,IF(WBS!$L5="Blocked",4,IF(WBS!$L5="Deferred",5,1)))),"")) | N5: =IF(OR(WBS!$F5="",WBS!$T5=""),"",IF(AND(9>=WBS!$F5,9<=WBS!$T5),IF(WBS!$L5="Done",3,IF(WBS!$L5="Doing",2,IF(WBS!$L5="Blocked",4,IF(WBS!$L5="Deferred",5,1)))),"")) | O5: =IF(OR(WBS!$F5="",WBS!$T5=""),"",IF(AND(10>=WBS!$F5,10<=WBS!$T5),IF(WBS!$L5="Done",3,IF(WBS!$L5="Doing",2,IF(WBS!$L5="Blocked",4,IF(WBS!$L5="Deferred",5,1)))),"")) | P5: =IF(OR(WBS!$F5="",WBS!$T5=""),"",IF(AND(11>=WBS!$F5,11<=WBS!$T5),IF(WBS!$L5="Done",3,IF(WBS!$L5="Doing",2,IF(WBS!$L5="Blocked",4,IF(WBS!$L5="Deferred",5,1)))),"")) | Q5: =IF(OR(WBS!$F5="",WBS!$T5=""),"",IF(AND(12>=WBS!$F5,12<=WBS!$T5),IF(WBS!$L5="Done",3,IF(WBS!$L5="Doing",2,IF(WBS!$L5="Blocked",4,IF(WBS!$L5="Deferred",5,1)))),"")) | R5: =IF(OR(WBS!$F5="",WBS!$T5=""),"",IF(AND(13>=WBS!$F5,13<=WBS!$T5),IF(WBS!$L5="Done",3,IF(WBS!$L5="Doing",2,IF(WBS!$L5="Blocked",4,IF(WBS!$L5="Deferred",5,1)))),"")) | S5: =IF(OR(WBS!$F5="",WBS!$T5=""),"",IF(AND(14>=WBS!$F5,14<=WBS!$T5),IF(WBS!$L5="Done",3,IF(WBS!$L5="Doing",2,IF(WBS!$L5="Blocked",4,IF(WBS!$L5="Deferred",5,1)))),"")) | T5: =IF(OR(WBS!$F5="",WBS!$T5=""),"",IF(AND(15>=WBS!$F5,15<=WBS!$T5),IF(WBS!$L5="Done",3,IF(WBS!$L5="Doing",2,IF(WBS!$L5="Blocked",4,IF(WBS!$L5="Deferred",5,1)))),"")) | U5: =IF(OR(WBS!$F5="",WBS!$T5=""),"",IF(AND(16>=WBS!$F5,16<=WBS!$T5),IF(WBS!$L5="Done",3,IF(WBS!$L5="Doing",2,IF(WBS!$L5="Blocked",4,IF(WBS!$L5="Deferred",5,1)))),"")) | V5: =IF(OR(WBS!$F5="",WBS!$T5=""),"",IF(AND(17>=WBS!$F5,17<=WBS!$T5),IF(WBS!$L5="Done",3,IF(WBS!$L5="Doing",2,IF(WBS!$L5="Blocked",4,IF(WBS!$L5="Deferred",5,1)))),"")) | W5: =IF(OR(WBS!$F5="",WBS!$T5=""),"",IF(AND(18>=WBS!$F5,18<=WBS!$T5),IF(WBS!$L5="Done",3,IF(WBS!$L5="Doing",2,IF(WBS!$L5="Blocked",4,IF(WBS!$L5="Deferred",5,1)))),"")) | X5: =IF(OR(WBS!$F5="",WBS!$T5=""),"",IF(AND(19>=WBS!$F5,19<=WBS!$T5),IF(WBS!$L5="Done",3,IF(WBS!$L5="Doing",2,IF(WBS!$L5="Blocked",4,IF(WBS!$L5="Deferred",5,1)))),"")) | Y5: =IF(OR(WBS!$F5="",WBS!$T5=""),"",IF(AND(20>=WBS!$F5,20<=WBS!$T5),IF(WBS!$L5="Done",3,IF(WBS!$L5="Doing",2,IF(WBS!$L5="Blocked",4,IF(WBS!$L5="Deferred",5,1)))),"")) | Z5: =IF(OR(WBS!$F5="",WBS!$T5=""),"",IF(AND(21>=WBS!$F5,21<=WBS!$T5),IF(WBS!$L5="Done",3,IF(WBS!$L5="Doing",2,IF(WBS!$L5="Blocked",4,IF(WBS!$L5="Deferred",5,1)))),""))
A6: =WBS!$A6 -> 1.1 | B6: =WBS!$C6 -> Brief analysis and gap discovery | C6: =IF(WBS!$E6="","",WBS!$E6) | D6: =WBS!$J6 -> 6 | E6: =WBS!$M6 -> 0 | F6: =IF(OR(WBS!$F6="",WBS!$T6=""),"",IF(AND(1>=WBS!$F6,1<=WBS!$T6),IF(WBS!$L6="Done",3,IF(WBS!$L6="Doing",2,IF(WBS!$L6="Blocked",4,IF(WBS!$L6="Deferred",5,1)))),"")) -> 1 | G6: =IF(OR(WBS!$F6="",WBS!$T6=""),"",IF(AND(2>=WBS!$F6,2<=WBS!$T6),IF(WBS!$L6="Done",3,IF(WBS!$L6="Doing",2,IF(WBS!$L6="Blocked",4,IF(WBS!$L6="Deferred",5,1)))),"")) -> 1 | H6: =IF(OR(WBS!$F6="",WBS!$T6=""),"",IF(AND(3>=WBS!$F6,3<=WBS!$T6),IF(WBS!$L6="Done",3,IF(WBS!$L6="Doing",2,IF(WBS!$L6="Blocked",4,IF(WBS!$L6="Deferred",5,1)))),"")) | I6: =IF(OR(WBS!$F6="",WBS!$T6=""),"",IF(AND(4>=WBS!$F6,4<=WBS!$T6),IF(WBS!$L6="Done",3,IF(WBS!$L6="Doing",2,IF(WBS!$L6="Blocked",4,IF(WBS!$L6="Deferred",5,1)))),"")) | J6: =IF(OR(WBS!$F6="",WBS!$T6=""),"",IF(AND(5>=WBS!$F6,5<=WBS!$T6),IF(WBS!$L6="Done",3,IF(WBS!$L6="Doing",2,IF(WBS!$L6="Blocked",4,IF(WBS!$L6="Deferred",5,1)))),"")) | K6: =IF(OR(WBS!$F6="",WBS!$T6=""),"",IF(AND(6>=WBS!$F6,6<=WBS!$T6),IF(WBS!$L6="Done",3,IF(WBS!$L6="Doing",2,IF(WBS!$L6="Blocked",4,IF(WBS!$L6="Deferred",5,1)))),"")) | L6: =IF(OR(WBS!$F6="",WBS!$T6=""),"",IF(AND(7>=WBS!$F6,7<=WBS!$T6),IF(WBS!$L6="Done",3,IF(WBS!$L6="Doing",2,IF(WBS!$L6="Blocked",4,IF(WBS!$L6="Deferred",5,1)))),"")) | M6: =IF(OR(WBS!$F6="",WBS!$T6=""),"",IF(AND(8>=WBS!$F6,8<=WBS!$T6),IF(WBS!$L6="Done",3,IF(WBS!$L6="Doing",2,IF(WBS!$L6="Blocked",4,IF(WBS!$L6="Deferred",5,1)))),"")) | N6: =IF(OR(WBS!$F6="",WBS!$T6=""),"",IF(AND(9>=WBS!$F6,9<=WBS!$T6),IF(WBS!$L6="Done",3,IF(WBS!$L6="Doing",2,IF(WBS!$L6="Blocked",4,IF(WBS!$L6="Deferred",5,1)))),"")) | O6: =IF(OR(WBS!$F6="",WBS!$T6=""),"",IF(AND(10>=WBS!$F6,10<=WBS!$T6),IF(WBS!$L6="Done",3,IF(WBS!$L6="Doing",2,IF(WBS!$L6="Blocked",4,IF(WBS!$L6="Deferred",5,1)))),"")) | P6: =IF(OR(WBS!$F6="",WBS!$T6=""),"",IF(AND(11>=WBS!$F6,11<=WBS!$T6),IF(WBS!$L6="Done",3,IF(WBS!$L6="Doing",2,IF(WBS!$L6="Blocked",4,IF(WBS!$L6="Deferred",5,1)))),"")) | Q6: =IF(OR(WBS!$F6="",WBS!$T6=""),"",IF(AND(12>=WBS!$F6,12<=WBS!$T6),IF(WBS!$L6="Done",3,IF(WBS!$L6="Doing",2,IF(WBS!$L6="Blocked",4,IF(WBS!$L6="Deferred",5,1)))),"")) | R6: =IF(OR(WBS!$F6="",WBS!$T6=""),"",IF(AND(13>=WBS!$F6,13<=WBS!$T6),IF(WBS!$L6="Done",3,IF(WBS!$L6="Doing",2,IF(WBS!$L6="Blocked",4,IF(WBS!$L6="Deferred",5,1)))),"")) | S6: =IF(OR(WBS!$F6="",WBS!$T6=""),"",IF(AND(14>=WBS!$F6,14<=WBS!$T6),IF(WBS!$L6="Done",3,IF(WBS!$L6="Doing",2,IF(WBS!$L6="Blocked",4,IF(WBS!$L6="Deferred",5,1)))),"")) | T6: =IF(OR(WBS!$F6="",WBS!$T6=""),"",IF(AND(15>=WBS!$F6,15<=WBS!$T6),IF(WBS!$L6="Done",3,IF(WBS!$L6="Doing",2,IF(WBS!$L6="Blocked",4,IF(WBS!$L6="Deferred",5,1)))),"")) | U6: =IF(OR(WBS!$F6="",WBS!$T6=""),"",IF(AND(16>=WBS!$F6,16<=WBS!$T6),IF(WBS!$L6="Done",3,IF(WBS!$L6="Doing",2,IF(WBS!$L6="Blocked",4,IF(WBS!$L6="Deferred",5,1)))),"")) | V6: =IF(OR(WBS!$F6="",WBS!$T6=""),"",IF(AND(17>=WBS!$F6,17<=WBS!$T6),IF(WBS!$L6="Done",3,IF(WBS!$L6="Doing",2,IF(WBS!$L6="Blocked",4,IF(WBS!$L6="Deferred",5,1)))),"")) | W6: =IF(OR(WBS!$F6="",WBS!$T6=""),"",IF(AND(18>=WBS!$F6,18<=WBS!$T6),IF(WBS!$L6="Done",3,IF(WBS!$L6="Doing",2,IF(WBS!$L6="Blocked",4,IF(WBS!$L6="Deferred",5,1)))),"")) | X6: =IF(OR(WBS!$F6="",WBS!$T6=""),"",IF(AND(19>=WBS!$F6,19<=WBS!$T6),IF(WBS!$L6="Done",3,IF(WBS!$L6="Doing",2,IF(WBS!$L6="Blocked",4,IF(WBS!$L6="Deferred",5,1)))),"")) | Y6: =IF(OR(WBS!$F6="",WBS!$T6=""),"",IF(AND(20>=WBS!$F6,20<=WBS!$T6),IF(WBS!$L6="Done",3,IF(WBS!$L6="Doing",2,IF(WBS!$L6="Blocked",4,IF(WBS!$L6="Deferred",5,1)))),"")) | Z6: =IF(OR(WBS!$F6="",WBS!$T6=""),"",IF(AND(21>=WBS!$F6,21<=WBS!$T6),IF(WBS!$L6="Done",3,IF(WBS!$L6="Doing",2,IF(WBS!$L6="Blocked",4,IF(WBS!$L6="Deferred",5,1)))),""))
A7: =WBS!$A7 -> 1.1.1 | B7: =WBS!$C7 -> Decompose brief into atomic statements tagged GIVEN / IMPLIED / ABSENT | C7: =IF(WBS!$E7="","",WBS!$E7) -> REQ | D7: =WBS!$J7 -> 3 | E7: =WBS!$M7 -> 0 | F7: =IF(OR(WBS!$F7="",WBS!$T7=""),"",IF(AND(1>=WBS!$F7,1<=WBS!$T7),IF(WBS!$L7="Done",3,IF(WBS!$L7="Doing",2,IF(WBS!$L7="Blocked",4,IF(WBS!$L7="Deferred",5,1)))),"")) -> 1 | G7: =IF(OR(WBS!$F7="",WBS!$T7=""),"",IF(AND(2>=WBS!$F7,2<=WBS!$T7),IF(WBS!$L7="Done",3,IF(WBS!$L7="Doing",2,IF(WBS!$L7="Blocked",4,IF(WBS!$L7="Deferred",5,1)))),"")) | H7: =IF(OR(WBS!$F7="",WBS!$T7=""),"",IF(AND(3>=WBS!$F7,3<=WBS!$T7),IF(WBS!$L7="Done",3,IF(WBS!$L7="Doing",2,IF(WBS!$L7="Blocked",4,IF(WBS!$L7="Deferred",5,1)))),"")) | I7: =IF(OR(WBS!$F7="",WBS!$T7=""),"",IF(AND(4>=WBS!$F7,4<=WBS!$T7),IF(WBS!$L7="Done",3,IF(WBS!$L7="Doing",2,IF(WBS!$L7="Blocked",4,IF(WBS!$L7="Deferred",5,1)))),"")) | J7: =IF(OR(WBS!$F7="",WBS!$T7=""),"",IF(AND(5>=WBS!$F7,5<=WBS!$T7),IF(WBS!$L7="Done",3,IF(WBS!$L7="Doing",2,IF(WBS!$L7="Blocked",4,IF(WBS!$L7="Deferred",5,1)))),"")) | K7: =IF(OR(WBS!$F7="",WBS!$T7=""),"",IF(AND(6>=WBS!$F7,6<=WBS!$T7),IF(WBS!$L7="Done",3,IF(WBS!$L7="Doing",2,IF(WBS!$L7="Blocked",4,IF(WBS!$L7="Deferred",5,1)))),"")) | L7: =IF(OR(WBS!$F7="",WBS!$T7=""),"",IF(AND(7>=WBS!$F7,7<=WBS!$T7),IF(WBS!$L7="Done",3,IF(WBS!$L7="Doing",2,IF(WBS!$L7="Blocked",4,IF(WBS!$L7="Deferred",5,1)))),"")) | M7: =IF(OR(WBS!$F7="",WBS!$T7=""),"",IF(AND(8>=WBS!$F7,8<=WBS!$T7),IF(WBS!$L7="Done",3,IF(WBS!$L7="Doing",2,IF(WBS!$L7="Blocked",4,IF(WBS!$L7="Deferred",5,1)))),"")) | N7: =IF(OR(WBS!$F7="",WBS!$T7=""),"",IF(AND(9>=WBS!$F7,9<=WBS!$T7),IF(WBS!$L7="Done",3,IF(WBS!$L7="Doing",2,IF(WBS!$L7="Blocked",4,IF(WBS!$L7="Deferred",5,1)))),"")) | O7: =IF(OR(WBS!$F7="",WBS!$T7=""),"",IF(AND(10>=WBS!$F7,10<=WBS!$T7),IF(WBS!$L7="Done",3,IF(WBS!$L7="Doing",2,IF(WBS!$L7="Blocked",4,IF(WBS!$L7="Deferred",5,1)))),"")) | P7: =IF(OR(WBS!$F7="",WBS!$T7=""),"",IF(AND(11>=WBS!$F7,11<=WBS!$T7),IF(WBS!$L7="Done",3,IF(WBS!$L7="Doing",2,IF(WBS!$L7="Blocked",4,IF(WBS!$L7="Deferred",5,1)))),"")) | Q7: =IF(OR(WBS!$F7="",WBS!$T7=""),"",IF(AND(12>=WBS!$F7,12<=WBS!$T7),IF(WBS!$L7="Done",3,IF(WBS!$L7="Doing",2,IF(WBS!$L7="Blocked",4,IF(WBS!$L7="Deferred",5,1)))),"")) | R7: =IF(OR(WBS!$F7="",WBS!$T7=""),"",IF(AND(13>=WBS!$F7,13<=WBS!$T7),IF(WBS!$L7="Done",3,IF(WBS!$L7="Doing",2,IF(WBS!$L7="Blocked",4,IF(WBS!$L7="Deferred",5,1)))),"")) | S7: =IF(OR(WBS!$F7="",WBS!$T7=""),"",IF(AND(14>=WBS!$F7,14<=WBS!$T7),IF(WBS!$L7="Done",3,IF(WBS!$L7="Doing",2,IF(WBS!$L7="Blocked",4,IF(WBS!$L7="Deferred",5,1)))),"")) | T7: =IF(OR(WBS!$F7="",WBS!$T7=""),"",IF(AND(15>=WBS!$F7,15<=WBS!$T7),IF(WBS!$L7="Done",3,IF(WBS!$L7="Doing",2,IF(WBS!$L7="Blocked",4,IF(WBS!$L7="Deferred",5,1)))),"")) | U7: =IF(OR(WBS!$F7="",WBS!$T7=""),"",IF(AND(16>=WBS!$F7,16<=WBS!$T7),IF(WBS!$L7="Done",3,IF(WBS!$L7="Doing",2,IF(WBS!$L7="Blocked",4,IF(WBS!$L7="Deferred",5,1)))),"")) | V7: =IF(OR(WBS!$F7="",WBS!$T7=""),"",IF(AND(17>=WBS!$F7,17<=WBS!$T7),IF(WBS!$L7="Done",3,IF(WBS!$L7="Doing",2,IF(WBS!$L7="Blocked",4,IF(WBS!$L7="Deferred",5,1)))),"")) | W7: =IF(OR(WBS!$F7="",WBS!$T7=""),"",IF(AND(18>=WBS!$F7,18<=WBS!$T7),IF(WBS!$L7="Done",3,IF(WBS!$L7="Doing",2,IF(WBS!$L7="Blocked",4,IF(WBS!$L7="Deferred",5,1)))),"")) | X7: =IF(OR(WBS!$F7="",WBS!$T7=""),"",IF(AND(19>=WBS!$F7,19<=WBS!$T7),IF(WBS!$L7="Done",3,IF(WBS!$L7="Doing",2,IF(WBS!$L7="Blocked",4,IF(WBS!$L7="Deferred",5,1)))),"")) | Y7: =IF(OR(WBS!$F7="",WBS!$T7=""),"",IF(AND(20>=WBS!$F7,20<=WBS!$T7),IF(WBS!$L7="Done",3,IF(WBS!$L7="Doing",2,IF(WBS!$L7="Blocked",4,IF(WBS!$L7="Deferred",5,1)))),"")) | Z7: =IF(OR(WBS!$F7="",WBS!$T7=""),"",IF(AND(21>=WBS!$F7,21<=WBS!$T7),IF(WBS!$L7="Done",3,IF(WBS!$L7="Doing",2,IF(WBS!$L7="Blocked",4,IF(WBS!$L7="Deferred",5,1)))),""))
A8: =WBS!$A8 -> 1.1.2 | B8: =WBS!$C8 -> Convert plan section 6 findings into REQ / ASM / EDG / OQ entries | C8: =IF(WBS!$E8="","",WBS!$E8) -> REQ | D8: =WBS!$J8 -> 2 | E8: =WBS!$M8 -> 0 | F8: =IF(OR(WBS!$F8="",WBS!$T8=""),"",IF(AND(1>=WBS!$F8,1<=WBS!$T8),IF(WBS!$L8="Done",3,IF(WBS!$L8="Doing",2,IF(WBS!$L8="Blocked",4,IF(WBS!$L8="Deferred",5,1)))),"")) | G8: =IF(OR(WBS!$F8="",WBS!$T8=""),"",IF(AND(2>=WBS!$F8,2<=WBS!$T8),IF(WBS!$L8="Done",3,IF(WBS!$L8="Doing",2,IF(WBS!$L8="Blocked",4,IF(WBS!$L8="Deferred",5,1)))),"")) -> 1 | H8: =IF(OR(WBS!$F8="",WBS!$T8=""),"",IF(AND(3>=WBS!$F8,3<=WBS!$T8),IF(WBS!$L8="Done",3,IF(WBS!$L8="Doing",2,IF(WBS!$L8="Blocked",4,IF(WBS!$L8="Deferred",5,1)))),"")) | I8: =IF(OR(WBS!$F8="",WBS!$T8=""),"",IF(AND(4>=WBS!$F8,4<=WBS!$T8),IF(WBS!$L8="Done",3,IF(WBS!$L8="Doing",2,IF(WBS!$L8="Blocked",4,IF(WBS!$L8="Deferred",5,1)))),"")) | J8: =IF(OR(WBS!$F8="",WBS!$T8=""),"",IF(AND(5>=WBS!$F8,5<=WBS!$T8),IF(WBS!$L8="Done",3,IF(WBS!$L8="Doing",2,IF(WBS!$L8="Blocked",4,IF(WBS!$L8="Deferred",5,1)))),"")) | K8: =IF(OR(WBS!$F8="",WBS!$T8=""),"",IF(AND(6>=WBS!$F8,6<=WBS!$T8),IF(WBS!$L8="Done",3,IF(WBS!$L8="Doing",2,IF(WBS!$L8="Blocked",4,IF(WBS!$L8="Deferred",5,1)))),"")) | L8: =IF(OR(WBS!$F8="",WBS!$T8=""),"",IF(AND(7>=WBS!$F8,7<=WBS!$T8),IF(WBS!$L8="Done",3,IF(WBS!$L8="Doing",2,IF(WBS!$L8="Blocked",4,IF(WBS!$L8="Deferred",5,1)))),"")) | M8: =IF(OR(WBS!$F8="",WBS!$T8=""),"",IF(AND(8>=WBS!$F8,8<=WBS!$T8),IF(WBS!$L8="Done",3,IF(WBS!$L8="Doing",2,IF(WBS!$L8="Blocked",4,IF(WBS!$L8="Deferred",5,1)))),"")) | N8: =IF(OR(WBS!$F8="",WBS!$T8=""),"",IF(AND(9>=WBS!$F8,9<=WBS!$T8),IF(WBS!$L8="Done",3,IF(WBS!$L8="Doing",2,IF(WBS!$L8="Blocked",4,IF(WBS!$L8="Deferred",5,1)))),"")) | O8: =IF(OR(WBS!$F8="",WBS!$T8=""),"",IF(AND(10>=WBS!$F8,10<=WBS!$T8),IF(WBS!$L8="Done",3,IF(WBS!$L8="Doing",2,IF(WBS!$L8="Blocked",4,IF(WBS!$L8="Deferred",5,1)))),"")) | P8: =IF(OR(WBS!$F8="",WBS!$T8=""),"",IF(AND(11>=WBS!$F8,11<=WBS!$T8),IF(WBS!$L8="Done",3,IF(WBS!$L8="Doing",2,IF(WBS!$L8="Blocked",4,IF(WBS!$L8="Deferred",5,1)))),"")) | Q8: =IF(OR(WBS!$F8="",WBS!$T8=""),"",IF(AND(12>=WBS!$F8,12<=WBS!$T8),IF(WBS!$L8="Done",3,IF(WBS!$L8="Doing",2,IF(WBS!$L8="Blocked",4,IF(WBS!$L8="Deferred",5,1)))),"")) | R8: =IF(OR(WBS!$F8="",WBS!$T8=""),"",IF(AND(13>=WBS!$F8,13<=WBS!$T8),IF(WBS!$L8="Done",3,IF(WBS!$L8="Doing",2,IF(WBS!$L8="Blocked",4,IF(WBS!$L8="Deferred",5,1)))),"")) | S8: =IF(OR(WBS!$F8="",WBS!$T8=""),"",IF(AND(14>=WBS!$F8,14<=WBS!$T8),IF(WBS!$L8="Done",3,IF(WBS!$L8="Doing",2,IF(WBS!$L8="Blocked",4,IF(WBS!$L8="Deferred",5,1)))),"")) | T8: =IF(OR(WBS!$F8="",WBS!$T8=""),"",IF(AND(15>=WBS!$F8,15<=WBS!$T8),IF(WBS!$L8="Done",3,IF(WBS!$L8="Doing",2,IF(WBS!$L8="Blocked",4,IF(WBS!$L8="Deferred",5,1)))),"")) | U8: =IF(OR(WBS!$F8="",WBS!$T8=""),"",IF(AND(16>=WBS!$F8,16<=WBS!$T8),IF(WBS!$L8="Done",3,IF(WBS!$L8="Doing",2,IF(WBS!$L8="Blocked",4,IF(WBS!$L8="Deferred",5,1)))),"")) | V8: =IF(OR(WBS!$F8="",WBS!$T8=""),"",IF(AND(17>=WBS!$F8,17<=WBS!$T8),IF(WBS!$L8="Done",3,IF(WBS!$L8="Doing",2,IF(WBS!$L8="Blocked",4,IF(WBS!$L8="Deferred",5,1)))),"")) | W8: =IF(OR(WBS!$F8="",WBS!$T8=""),"",IF(AND(18>=WBS!$F8,18<=WBS!$T8),IF(WBS!$L8="Done",3,IF(WBS!$L8="Doing",2,IF(WBS!$L8="Blocked",4,IF(WBS!$L8="Deferred",5,1)))),"")) | X8: =IF(OR(WBS!$F8="",WBS!$T8=""),"",IF(AND(19>=WBS!$F8,19<=WBS!$T8),IF(WBS!$L8="Done",3,IF(WBS!$L8="Doing",2,IF(WBS!$L8="Blocked",4,IF(WBS!$L8="Deferred",5,1)))),"")) | Y8: =IF(OR(WBS!$F8="",WBS!$T8=""),"",IF(AND(20>=WBS!$F8,20<=WBS!$T8),IF(WBS!$L8="Done",3,IF(WBS!$L8="Doing",2,IF(WBS!$L8="Blocked",4,IF(WBS!$L8="Deferred",5,1)))),"")) | Z8: =IF(OR(WBS!$F8="",WBS!$T8=""),"",IF(AND(21>=WBS!$F8,21<=WBS!$T8),IF(WBS!$L8="Done",3,IF(WBS!$L8="Doing",2,IF(WBS!$L8="Blocked",4,IF(WBS!$L8="Deferred",5,1)))),""))
A9: =WBS!$A9 -> 1.1.3 | B9: =WBS!$C9 -> Assumptions register with rationale | C9: =IF(WBS!$E9="","",WBS!$E9) -> REQ | D9: =WBS!$J9 -> 1 | E9: =WBS!$M9 -> 0 | F9: =IF(OR(WBS!$F9="",WBS!$T9=""),"",IF(AND(1>=WBS!$F9,1<=WBS!$T9),IF(WBS!$L9="Done",3,IF(WBS!$L9="Doing",2,IF(WBS!$L9="Blocked",4,IF(WBS!$L9="Deferred",5,1)))),"")) | G9: =IF(OR(WBS!$F9="",WBS!$T9=""),"",IF(AND(2>=WBS!$F9,2<=WBS!$T9),IF(WBS!$L9="Done",3,IF(WBS!$L9="Doing",2,IF(WBS!$L9="Blocked",4,IF(WBS!$L9="Deferred",5,1)))),"")) -> 1 | H9: =IF(OR(WBS!$F9="",WBS!$T9=""),"",IF(AND(3>=WBS!$F9,3<=WBS!$T9),IF(WBS!$L9="Done",3,IF(WBS!$L9="Doing",2,IF(WBS!$L9="Blocked",4,IF(WBS!$L9="Deferred",5,1)))),"")) | I9: =IF(OR(WBS!$F9="",WBS!$T9=""),"",IF(AND(4>=WBS!$F9,4<=WBS!$T9),IF(WBS!$L9="Done",3,IF(WBS!$L9="Doing",2,IF(WBS!$L9="Blocked",4,IF(WBS!$L9="Deferred",5,1)))),"")) | J9: =IF(OR(WBS!$F9="",WBS!$T9=""),"",IF(AND(5>=WBS!$F9,5<=WBS!$T9),IF(WBS!$L9="Done",3,IF(WBS!$L9="Doing",2,IF(WBS!$L9="Blocked",4,IF(WBS!$L9="Deferred",5,1)))),"")) | K9: =IF(OR(WBS!$F9="",WBS!$T9=""),"",IF(AND(6>=WBS!$F9,6<=WBS!$T9),IF(WBS!$L9="Done",3,IF(WBS!$L9="Doing",2,IF(WBS!$L9="Blocked",4,IF(WBS!$L9="Deferred",5,1)))),"")) | L9: =IF(OR(WBS!$F9="",WBS!$T9=""),"",IF(AND(7>=WBS!$F9,7<=WBS!$T9),IF(WBS!$L9="Done",3,IF(WBS!$L9="Doing",2,IF(WBS!$L9="Blocked",4,IF(WBS!$L9="Deferred",5,1)))),"")) | M9: =IF(OR(WBS!$F9="",WBS!$T9=""),"",IF(AND(8>=WBS!$F9,8<=WBS!$T9),IF(WBS!$L9="Done",3,IF(WBS!$L9="Doing",2,IF(WBS!$L9="Blocked",4,IF(WBS!$L9="Deferred",5,1)))),"")) | N9: =IF(OR(WBS!$F9="",WBS!$T9=""),"",IF(AND(9>=WBS!$F9,9<=WBS!$T9),IF(WBS!$L9="Done",3,IF(WBS!$L9="Doing",2,IF(WBS!$L9="Blocked",4,IF(WBS!$L9="Deferred",5,1)))),"")) | O9: =IF(OR(WBS!$F9="",WBS!$T9=""),"",IF(AND(10>=WBS!$F9,10<=WBS!$T9),IF(WBS!$L9="Done",3,IF(WBS!$L9="Doing",2,IF(WBS!$L9="Blocked",4,IF(WBS!$L9="Deferred",5,1)))),"")) | P9: =IF(OR(WBS!$F9="",WBS!$T9=""),"",IF(AND(11>=WBS!$F9,11<=WBS!$T9),IF(WBS!$L9="Done",3,IF(WBS!$L9="Doing",2,IF(WBS!$L9="Blocked",4,IF(WBS!$L9="Deferred",5,1)))),"")) | Q9: =IF(OR(WBS!$F9="",WBS!$T9=""),"",IF(AND(12>=WBS!$F9,12<=WBS!$T9),IF(WBS!$L9="Done",3,IF(WBS!$L9="Doing",2,IF(WBS!$L9="Blocked",4,IF(WBS!$L9="Deferred",5,1)))),"")) | R9: =IF(OR(WBS!$F9="",WBS!$T9=""),"",IF(AND(13>=WBS!$F9,13<=WBS!$T9),IF(WBS!$L9="Done",3,IF(WBS!$L9="Doing",2,IF(WBS!$L9="Blocked",4,IF(WBS!$L9="Deferred",5,1)))),"")) | S9: =IF(OR(WBS!$F9="",WBS!$T9=""),"",IF(AND(14>=WBS!$F9,14<=WBS!$T9),IF(WBS!$L9="Done",3,IF(WBS!$L9="Doing",2,IF(WBS!$L9="Blocked",4,IF(WBS!$L9="Deferred",5,1)))),"")) | T9: =IF(OR(WBS!$F9="",WBS!$T9=""),"",IF(AND(15>=WBS!$F9,15<=WBS!$T9),IF(WBS!$L9="Done",3,IF(WBS!$L9="Doing",2,IF(WBS!$L9="Blocked",4,IF(WBS!$L9="Deferred",5,1)))),"")) | U9: =IF(OR(WBS!$F9="",WBS!$T9=""),"",IF(AND(16>=WBS!$F9,16<=WBS!$T9),IF(WBS!$L9="Done",3,IF(WBS!$L9="Doing",2,IF(WBS!$L9="Blocked",4,IF(WBS!$L9="Deferred",5,1)))),"")) | V9: =IF(OR(WBS!$F9="",WBS!$T9=""),"",IF(AND(17>=WBS!$F9,17<=WBS!$T9),IF(WBS!$L9="Done",3,IF(WBS!$L9="Doing",2,IF(WBS!$L9="Blocked",4,IF(WBS!$L9="Deferred",5,1)))),"")) | W9: =IF(OR(WBS!$F9="",WBS!$T9=""),"",IF(AND(18>=WBS!$F9,18<=WBS!$T9),IF(WBS!$L9="Done",3,IF(WBS!$L9="Doing",2,IF(WBS!$L9="Blocked",4,IF(WBS!$L9="Deferred",5,1)))),"")) | X9: =IF(OR(WBS!$F9="",WBS!$T9=""),"",IF(AND(19>=WBS!$F9,19<=WBS!$T9),IF(WBS!$L9="Done",3,IF(WBS!$L9="Doing",2,IF(WBS!$L9="Blocked",4,IF(WBS!$L9="Deferred",5,1)))),"")) | Y9: =IF(OR(WBS!$F9="",WBS!$T9=""),"",IF(AND(20>=WBS!$F9,20<=WBS!$T9),IF(WBS!$L9="Done",3,IF(WBS!$L9="Doing",2,IF(WBS!$L9="Blocked",4,IF(WBS!$L9="Deferred",5,1)))),"")) | Z9: =IF(OR(WBS!$F9="",WBS!$T9=""),"",IF(AND(21>=WBS!$F9,21<=WBS!$T9),IF(WBS!$L9="Done",3,IF(WBS!$L9="Doing",2,IF(WBS!$L9="Blocked",4,IF(WBS!$L9="Deferred",5,1)))),""))
A10: =WBS!$A10 -> 1.2 | B10: =WBS!$C10 -> Stakeholder simulation | C10: =IF(WBS!$E10="","",WBS!$E10) | D10: =WBS!$J10 -> 10 | E10: =WBS!$M10 -> 0 | F10: =IF(OR(WBS!$F10="",WBS!$T10=""),"",IF(AND(1>=WBS!$F10,1<=WBS!$T10),IF(WBS!$L10="Done",3,IF(WBS!$L10="Doing",2,IF(WBS!$L10="Blocked",4,IF(WBS!$L10="Deferred",5,1)))),"")) -> 1 | G10: =IF(OR(WBS!$F10="",WBS!$T10=""),"",IF(AND(2>=WBS!$F10,2<=WBS!$T10),IF(WBS!$L10="Done",3,IF(WBS!$L10="Doing",2,IF(WBS!$L10="Blocked",4,IF(WBS!$L10="Deferred",5,1)))),"")) -> 1 | H10: =IF(OR(WBS!$F10="",WBS!$T10=""),"",IF(AND(3>=WBS!$F10,3<=WBS!$T10),IF(WBS!$L10="Done",3,IF(WBS!$L10="Doing",2,IF(WBS!$L10="Blocked",4,IF(WBS!$L10="Deferred",5,1)))),"")) -> 1 | I10: =IF(OR(WBS!$F10="",WBS!$T10=""),"",IF(AND(4>=WBS!$F10,4<=WBS!$T10),IF(WBS!$L10="Done",3,IF(WBS!$L10="Doing",2,IF(WBS!$L10="Blocked",4,IF(WBS!$L10="Deferred",5,1)))),"")) | J10: =IF(OR(WBS!$F10="",WBS!$T10=""),"",IF(AND(5>=WBS!$F10,5<=WBS!$T10),IF(WBS!$L10="Done",3,IF(WBS!$L10="Doing",2,IF(WBS!$L10="Blocked",4,IF(WBS!$L10="Deferred",5,1)))),"")) | K10: =IF(OR(WBS!$F10="",WBS!$T10=""),"",IF(AND(6>=WBS!$F10,6<=WBS!$T10),IF(WBS!$L10="Done",3,IF(WBS!$L10="Doing",2,IF(WBS!$L10="Blocked",4,IF(WBS!$L10="Deferred",5,1)))),"")) | L10: =IF(OR(WBS!$F10="",WBS!$T10=""),"",IF(AND(7>=WBS!$F10,7<=WBS!$T10),IF(WBS!$L10="Done",3,IF(WBS!$L10="Doing",2,IF(WBS!$L10="Blocked",4,IF(WBS!$L10="Deferred",5,1)))),"")) | M10: =IF(OR(WBS!$F10="",WBS!$T10=""),"",IF(AND(8>=WBS!$F10,8<=WBS!$T10),IF(WBS!$L10="Done",3,IF(WBS!$L10="Doing",2,IF(WBS!$L10="Blocked",4,IF(WBS!$L10="Deferred",5,1)))),"")) | N10: =IF(OR(WBS!$F10="",WBS!$T10=""),"",IF(AND(9>=WBS!$F10,9<=WBS!$T10),IF(WBS!$L10="Done",3,IF(WBS!$L10="Doing",2,IF(WBS!$L10="Blocked",4,IF(WBS!$L10="Deferred",5,1)))),"")) | O10: =IF(OR(WBS!$F10="",WBS!$T10=""),"",IF(AND(10>=WBS!$F10,10<=WBS!$T10),IF(WBS!$L10="Done",3,IF(WBS!$L10="Doing",2,IF(WBS!$L10="Blocked",4,IF(WBS!$L10="Deferred",5,1)))),"")) | P10: =IF(OR(WBS!$F10="",WBS!$T10=""),"",IF(AND(11>=WBS!$F10,11<=WBS!$T10),IF(WBS!$L10="Done",3,IF(WBS!$L10="Doing",2,IF(WBS!$L10="Blocked",4,IF(WBS!$L10="Deferred",5,1)))),"")) | Q10: =IF(OR(WBS!$F10="",WBS!$T10=""),"",IF(AND(12>=WBS!$F10,12<=WBS!$T10),IF(WBS!$L10="Done",3,IF(WBS!$L10="Doing",2,IF(WBS!$L10="Blocked",4,IF(WBS!$L10="Deferred",5,1)))),"")) | R10: =IF(OR(WBS!$F10="",WBS!$T10=""),"",IF(AND(13>=WBS!$F10,13<=WBS!$T10),IF(WBS!$L10="Done",3,IF(WBS!$L10="Doing",2,IF(WBS!$L10="Blocked",4,IF(WBS!$L10="Deferred",5,1)))),"")) | S10: =IF(OR(WBS!$F10="",WBS!$T10=""),"",IF(AND(14>=WBS!$F10,14<=WBS!$T10),IF(WBS!$L10="Done",3,IF(WBS!$L10="Doing",2,IF(WBS!$L10="Blocked",4,IF(WBS!$L10="Deferred",5,1)))),"")) | T10: =IF(OR(WBS!$F10="",WBS!$T10=""),"",IF(AND(15>=WBS!$F10,15<=WBS!$T10),IF(WBS!$L10="Done",3,IF(WBS!$L10="Doing",2,IF(WBS!$L10="Blocked",4,IF(WBS!$L10="Deferred",5,1)))),"")) | U10: =IF(OR(WBS!$F10="",WBS!$T10=""),"",IF(AND(16>=WBS!$F10,16<=WBS!$T10),IF(WBS!$L10="Done",3,IF(WBS!$L10="Doing",2,IF(WBS!$L10="Blocked",4,IF(WBS!$L10="Deferred",5,1)))),"")) | V10: =IF(OR(WBS!$F10="",WBS!$T10=""),"",IF(AND(17>=WBS!$F10,17<=WBS!$T10),IF(WBS!$L10="Done",3,IF(WBS!$L10="Doing",2,IF(WBS!$L10="Blocked",4,IF(WBS!$L10="Deferred",5,1)))),"")) | W10: =IF(OR(WBS!$F10="",WBS!$T10=""),"",IF(AND(18>=WBS!$F10,18<=WBS!$T10),IF(WBS!$L10="Done",3,IF(WBS!$L10="Doing",2,IF(WBS!$L10="Blocked",4,IF(WBS!$L10="Deferred",5,1)))),"")) | X10: =IF(OR(WBS!$F10="",WBS!$T10=""),"",IF(AND(19>=WBS!$F10,19<=WBS!$T10),IF(WBS!$L10="Done",3,IF(WBS!$L10="Doing",2,IF(WBS!$L10="Blocked",4,IF(WBS!$L10="Deferred",5,1)))),"")) | Y10: =IF(OR(WBS!$F10="",WBS!$T10=""),"",IF(AND(20>=WBS!$F10,20<=WBS!$T10),IF(WBS!$L10="Done",3,IF(WBS!$L10="Doing",2,IF(WBS!$L10="Blocked",4,IF(WBS!$L10="Deferred",5,1)))),"")) | Z10: =IF(OR(WBS!$F10="",WBS!$T10=""),"",IF(AND(21>=WBS!$F10,21<=WBS!$T10),IF(WBS!$L10="Done",3,IF(WBS!$L10="Doing",2,IF(WBS!$L10="Blocked",4,IF(WBS!$L10="Deferred",5,1)))),""))
